[2020-07-27 14:52:14,738] [INFO]: http://3.215.183.155/static/so/so_5f113c6d09ca0c419118e66c.pdf [in /home/ubuntu/SIH-2020/app/routes.py:559]
[2020-07-27 14:54:14,755] [INFO]: <Request 'http://3.215.183.155/api/services/v1/get_po_invoice' [POST]> [in /home/ubuntu/SIH-2020/app/routes.py:505]
[2020-07-27 14:54:14,756] [INFO]: reached po invoice 1 [in /home/ubuntu/SIH-2020/app/routes.py:511]
[2020-07-27 14:54:14,761] [ERROR]: Exception on /api/services/v1/get_po_invoice [POST] [in /usr/local/lib/python3.6/dist-packages/flask/app.py:1560]
Traceback (most recent call last):
  File "/home/ubuntu/SIH-2020/app/routes.py", line 514, in get_po_invoice
    content = db.po.find_one({'_id':ObjectId(data['Data']['po_id'])})
KeyError: 'po_id'

During handling of the above exception, another exception occurred:

Traceback (most recent call last):
  File "/usr/local/lib/python3.6/dist-packages/flask/app.py", line 1982, in wsgi_app
    response = self.full_dispatch_request()
  File "/usr/local/lib/python3.6/dist-packages/flask/app.py", line 1614, in full_dispatch_request
    rv = self.handle_user_exception(e)
  File "/usr/local/lib/python3.6/dist-packages/flask/app.py", line 1517, in handle_user_exception
    reraise(exc_type, exc_value, tb)
  File "/usr/local/lib/python3.6/dist-packages/flask/_compat.py", line 33, in reraise
    raise value
  File "/usr/local/lib/python3.6/dist-packages/flask/app.py", line 1612, in full_dispatch_request
    rv = self.dispatch_request()
  File "/usr/local/lib/python3.6/dist-packages/flask/app.py", line 1598, in dispatch_request
    return self.view_functions[rule.endpoint](**req.view_args)
  File "/home/ubuntu/SIH-2020/app/routes.py", line 528, in get_po_invoice
    logger.error(str(e) + "on line no: " + exc_tb.tb_lineno)
NameError: name 'logger' is not defined
[2020-07-27 14:59:25,174] [INFO]: <Request 'http://3.215.183.155/api/services/v1/get_so_invoice' [POST]> [in /home/ubuntu/SIH-2020/app/routes.py:540]
[2020-07-27 14:59:25,174] [INFO]: reached so invoice 1 [in /home/ubuntu/SIH-2020/app/routes.py:546]
[2020-07-27 14:59:25,179] [ERROR]: Exception on /api/services/v1/get_so_invoice [POST] [in /usr/local/lib/python3.6/dist-packages/flask/app.py:1560]
Traceback (most recent call last):
  File "/home/ubuntu/SIH-2020/app/routes.py", line 549, in get_so_invoice
    cont = db.so.find_one({'_id':ObjectId(data['Data']['so_id'])})
KeyError: 'so_id'

During handling of the above exception, another exception occurred:

Traceback (most recent call last):
  File "/usr/local/lib/python3.6/dist-packages/flask/app.py", line 1982, in wsgi_app
    response = self.full_dispatch_request()
  File "/usr/local/lib/python3.6/dist-packages/flask/app.py", line 1614, in full_dispatch_request
    rv = self.handle_user_exception(e)
  File "/usr/local/lib/python3.6/dist-packages/flask/app.py", line 1517, in handle_user_exception
    reraise(exc_type, exc_value, tb)
  File "/usr/local/lib/python3.6/dist-packages/flask/_compat.py", line 33, in reraise
    raise value
  File "/usr/local/lib/python3.6/dist-packages/flask/app.py", line 1612, in full_dispatch_request
    rv = self.dispatch_request()
  File "/usr/local/lib/python3.6/dist-packages/flask/app.py", line 1598, in dispatch_request
    return self.view_functions[rule.endpoint](**req.view_args)
  File "/home/ubuntu/SIH-2020/app/routes.py", line 564, in get_so_invoice
    logger.error(str(e) + "on line no: " + exc_tb.tb_lineno)
NameError: name 'logger' is not defined
[2020-07-27 14:59:29,352] [INFO]: <Request 'http://3.215.183.155/api/services/v1/get_so_invoice' [POST]> [in /home/ubuntu/SIH-2020/app/routes.py:540]
[2020-07-27 14:59:29,352] [INFO]: reached so invoice 1 [in /home/ubuntu/SIH-2020/app/routes.py:546]
[2020-07-27 14:59:29,361] [INFO]: so_5f113c6d09ca0c419118e66c.pdf [in /home/ubuntu/SIH-2020/app/routes.py:553]
[2020-07-27 14:59:29,435] [INFO]: http://3.215.183.155/static/so/so_5f113c6d09ca0c419118e66c.pdf [in /home/ubuntu/SIH-2020/app/routes.py:559]
[2020-07-27 15:08:00,024] [INFO]: {'provider': 'username', 'Data': {'serial_no': 'cUQWnX8AKYHmSPRo8Vegdk'}} [in /home/ubuntu/SIH-2020/app/routes.py:991]
[2020-07-27 15:17:43,306] [INFO]: {'provider': 'username', 'Data': {'serial_no': ' bis1'}} [in /home/ubuntu/SIH-2020/app/routes.py:991]
[2020-07-27 16:53:10,109] [ERROR]: Exception on /search [GET] [in /usr/local/lib/python3.6/dist-packages/flask/app.py:1560]
Traceback (most recent call last):
  File "/usr/local/lib/python3.6/dist-packages/flask/app.py", line 1982, in wsgi_app
    response = self.full_dispatch_request()
  File "/usr/local/lib/python3.6/dist-packages/flask/app.py", line 1614, in full_dispatch_request
    rv = self.handle_user_exception(e)
  File "/usr/local/lib/python3.6/dist-packages/flask/app.py", line 1517, in handle_user_exception
    reraise(exc_type, exc_value, tb)
  File "/usr/local/lib/python3.6/dist-packages/flask/_compat.py", line 33, in reraise
    raise value
  File "/usr/local/lib/python3.6/dist-packages/flask/app.py", line 1612, in full_dispatch_request
    rv = self.dispatch_request()
  File "/usr/local/lib/python3.6/dist-packages/flask/app.py", line 1598, in dispatch_request
    return self.view_functions[rule.endpoint](**req.view_args)
  File "/home/ubuntu/SIH-2020/app/routes.py", line 312, in search
    fin = mongo.db.users.find_one({ 'username':session['username'] })
  File "/usr/local/lib/python3.6/dist-packages/werkzeug/local.py", line 378, in <lambda>
    __getitem__ = lambda x, i: x._get_current_object()[i]
KeyError: 'username'
[2020-07-27 17:41:08,126] [INFO]: {'provider': 'username', 'Data': {'serial_no': ' try'}} [in /home/ubuntu/SIH-2020/app/routes.py:991]
[2020-07-27 17:42:48,019] [INFO]: {'provider': 'username', 'Data': {'serial_no': ' try'}} [in /home/ubuntu/SIH-2020/app/routes.py:991]
[2020-07-27 17:59:17,044] [INFO]: {'provider': 'username', 'Data': {'serial_no': ' '}} [in /home/ubuntu/SIH-2020/app/routes.py:991]
[2020-07-27 17:59:17,151] [INFO]: {'provider': 'username', 'Data': {'serial_no': ' '}} [in /home/ubuntu/SIH-2020/app/routes.py:991]
[2020-07-27 18:14:14,350] [INFO]: {'provider': 'username', 'Data': {'serial_no': ' '}} [in /home/ubuntu/SIH-2020/app/routes.py:991]
[2020-07-27 18:31:32,309] [INFO]: <Request 'http://3.215.183.155/api/services/v1/get_po_invoice' [POST]> [in /home/ubuntu/SIH-2020/app/routes.py:505]
[2020-07-27 18:31:32,309] [INFO]: reached po invoice 1 [in /home/ubuntu/SIH-2020/app/routes.py:511]
[2020-07-27 18:31:32,317] [INFO]: po_5f114408e257dd728e757d66.pdf [in /home/ubuntu/SIH-2020/app/routes.py:517]
[2020-07-27 18:31:32,391] [INFO]: http://3.215.183.155/static/po/po_5f114408e257dd728e757d66.pdf [in /home/ubuntu/SIH-2020/app/routes.py:523]
[2020-07-27 19:38:14,243] [INFO]: {'provider': 'username', 'Data': {'serial_no': ' '}} [in /home/ubuntu/SIH-2020/app/routes.py:991]
[2020-07-27 19:46:43,692] [INFO]: {'provider': 'username', 'Data': {'serial_no': ' '}} [in /home/ubuntu/SIH-2020/app/routes.py:991]
[2020-07-27 19:47:34,272] [INFO]: {'provider': 'username', 'Data': {'serial_no': ' '}} [in /home/ubuntu/SIH-2020/app/routes.py:991]
[2020-07-27 19:47:38,598] [INFO]: {'provider': 'username', 'Data': {'serial_no': ' '}} [in /home/ubuntu/SIH-2020/app/routes.py:991]
[2020-07-27 19:47:38,881] [INFO]: {'provider': 'username', 'Data': {'serial_no': ' '}} [in /home/ubuntu/SIH-2020/app/routes.py:991]
[2020-07-28 08:10:38,422] [INFO]: {'provider': 'username', 'Data': {'serial_no': ' '}} [in /home/ubuntu/SIH-2020/app/routes.py:991]
[2020-07-28 08:12:36,026] [INFO]: {'provider': 'username', 'Data': {'serial_no': ' '}} [in /home/ubuntu/SIH-2020/app/routes.py:991]
[2020-07-28 08:13:09,890] [INFO]: {'provider': 'username', 'Data': {'serial_no': ' '}} [in /home/ubuntu/SIH-2020/app/routes.py:991]
[2020-07-28 08:13:09,985] [INFO]: {'provider': 'username', 'Data': {'serial_no': ' '}} [in /home/ubuntu/SIH-2020/app/routes.py:991]
[2020-07-28 08:13:30,417] [INFO]: {'provider': 'username', 'Data': {'serial_no': ' '}} [in /home/ubuntu/SIH-2020/app/routes.py:991]
[2020-07-28 08:13:39,275] [INFO]: {'provider': 'username', 'Data': {'serial_no': ' '}} [in /home/ubuntu/SIH-2020/app/routes.py:991]
[2020-07-28 08:15:06,505] [INFO]: {'provider': 'username', 'Data': {'serial_no': ' '}} [in /home/ubuntu/SIH-2020/app/routes.py:991]
[2020-07-28 08:15:32,524] [INFO]: {'provider': 'username', 'Data': {'serial_no': ' '}} [in /home/ubuntu/SIH-2020/app/routes.py:991]
[2020-07-28 08:15:32,640] [INFO]: {'provider': 'username', 'Data': {'serial_no': ' '}} [in /home/ubuntu/SIH-2020/app/routes.py:991]
[2020-07-28 08:15:34,625] [INFO]: {'provider': 'username', 'Data': {'serial_no': ' '}} [in /home/ubuntu/SIH-2020/app/routes.py:991]
[2020-07-28 08:15:34,973] [INFO]: {'provider': 'username', 'Data': {'serial_no': ' '}} [in /home/ubuntu/SIH-2020/app/routes.py:991]
[2020-07-28 08:15:59,315] [INFO]: {'provider': 'username', 'Data': {'serial_no': ' '}} [in /home/ubuntu/SIH-2020/app/routes.py:991]
[2020-07-28 08:15:59,643] [INFO]: {'provider': 'username', 'Data': {'serial_no': ' '}} [in /home/ubuntu/SIH-2020/app/routes.py:991]
[2020-07-28 08:16:46,920] [INFO]: {'provider': 'username', 'Data': {'serial_no': ' '}} [in /home/ubuntu/SIH-2020/app/routes.py:991]
[2020-07-28 08:17:16,949] [INFO]: {'provider': 'username', 'Data': {'serial_no': ' '}} [in /home/ubuntu/SIH-2020/app/routes.py:991]
[2020-07-28 08:17:17,279] [INFO]: {'provider': 'username', 'Data': {'serial_no': ' '}} [in /home/ubuntu/SIH-2020/app/routes.py:991]
[2020-07-28 08:17:49,558] [INFO]: {'provider': 'username', 'Data': {'serial_no': ' '}} [in /home/ubuntu/SIH-2020/app/routes.py:991]
[2020-07-28 08:17:49,901] [INFO]: {'provider': 'username', 'Data': {'serial_no': ' '}} [in /home/ubuntu/SIH-2020/app/routes.py:991]
[2020-07-28 08:19:01,028] [INFO]: {'provider': 'username', 'Data': {'serial_no': ' '}} [in /home/ubuntu/SIH-2020/app/routes.py:991]
[2020-07-28 08:19:01,373] [INFO]: {'provider': 'username', 'Data': {'serial_no': ' '}} [in /home/ubuntu/SIH-2020/app/routes.py:991]
[2020-07-28 08:19:41,226] [INFO]: {'provider': 'username', 'Data': {'serial_no': ' '}} [in /home/ubuntu/SIH-2020/app/routes.py:991]
