[2020-08-01 08:17:21,513] [ERROR]: Exception on /api/services/v1/get_po_invoice [POST] [in /home/ubuntu/.local/lib/python3.6/site-packages/flask/app.py:1761]
Traceback (most recent call last):
  File "/home/ubuntu/SIH-2020/app/routes.py", line 512, in get_po_invoice
    content = db.po.find_one({'_id':ObjectId(data['Data']['po_id'])})
KeyError: 'po_id'

During handling of the above exception, another exception occurred:

Traceback (most recent call last):
  File "/home/ubuntu/.local/lib/python3.6/site-packages/flask/app.py", line 2292, in wsgi_app
    response = self.full_dispatch_request()
  File "/home/ubuntu/.local/lib/python3.6/site-packages/flask/app.py", line 1815, in full_dispatch_request
    rv = self.handle_user_exception(e)
  File "/home/ubuntu/.local/lib/python3.6/site-packages/flask/app.py", line 1718, in handle_user_exception
    reraise(exc_type, exc_value, tb)
  File "/home/ubuntu/.local/lib/python3.6/site-packages/flask/_compat.py", line 35, in reraise
    raise value
  File "/home/ubuntu/.local/lib/python3.6/site-packages/flask/app.py", line 1813, in full_dispatch_request
    rv = self.dispatch_request()
  File "/home/ubuntu/.local/lib/python3.6/site-packages/flask/app.py", line 1799, in dispatch_request
    return self.view_functions[rule.endpoint](**req.view_args)
  File "/home/ubuntu/SIH-2020/app/routes.py", line 526, in get_po_invoice
    logger.error(str(e) + "on line no: " + exc_tb.tb_lineno)
NameError: name 'logger' is not defined
[2020-08-01 08:17:26,706] [INFO]: <Request 'http://3.92.96.170/api/services/v1/get_po_invoice' [POST]> [in /home/ubuntu/SIH-2020/app/routes.py:503]
[2020-08-01 08:17:26,707] [INFO]: reached po invoice 1 [in /home/ubuntu/SIH-2020/app/routes.py:509]
[2020-08-01 08:17:26,715] [INFO]: po_5f157208ea95723b48ff59f7.pdf [in /home/ubuntu/SIH-2020/app/routes.py:515]
[2020-08-01 08:17:26,787] [INFO]: http://3.92.96.170/static/po/po_5f157208ea95723b48ff59f7.pdf [in /home/ubuntu/SIH-2020/app/routes.py:521]
[2020-08-01 08:17:27,303] [INFO]: <Request 'http://3.92.96.170/api/services/v1/get_po_invoice' [POST]> [in /home/ubuntu/SIH-2020/app/routes.py:503]
[2020-08-01 08:17:27,303] [INFO]: reached po invoice 1 [in /home/ubuntu/SIH-2020/app/routes.py:509]
[2020-08-01 08:17:27,308] [ERROR]: Exception on /api/services/v1/get_po_invoice [POST] [in /home/ubuntu/.local/lib/python3.6/site-packages/flask/app.py:1761]
Traceback (most recent call last):
  File "/home/ubuntu/SIH-2020/app/routes.py", line 512, in get_po_invoice
    content = db.po.find_one({'_id':ObjectId(data['Data']['po_id'])})
KeyError: 'po_id'

During handling of the above exception, another exception occurred:

Traceback (most recent call last):
  File "/home/ubuntu/.local/lib/python3.6/site-packages/flask/app.py", line 2292, in wsgi_app
    response = self.full_dispatch_request()
  File "/home/ubuntu/.local/lib/python3.6/site-packages/flask/app.py", line 1815, in full_dispatch_request
    rv = self.handle_user_exception(e)
  File "/home/ubuntu/.local/lib/python3.6/site-packages/flask/app.py", line 1718, in handle_user_exception
    reraise(exc_type, exc_value, tb)
  File "/home/ubuntu/.local/lib/python3.6/site-packages/flask/_compat.py", line 35, in reraise
    raise value
  File "/home/ubuntu/.local/lib/python3.6/site-packages/flask/app.py", line 1813, in full_dispatch_request
    rv = self.dispatch_request()
  File "/home/ubuntu/.local/lib/python3.6/site-packages/flask/app.py", line 1799, in dispatch_request
    return self.view_functions[rule.endpoint](**req.view_args)
  File "/home/ubuntu/SIH-2020/app/routes.py", line 526, in get_po_invoice
    logger.error(str(e) + "on line no: " + exc_tb.tb_lineno)
NameError: name 'logger' is not defined
[2020-08-01 08:17:32,121] [INFO]: <Request 'http://3.92.96.170/api/services/v1/get_po_invoice' [POST]> [in /home/ubuntu/SIH-2020/app/routes.py:503]
[2020-08-01 08:17:32,122] [INFO]: reached po invoice 1 [in /home/ubuntu/SIH-2020/app/routes.py:509]
[2020-08-01 08:17:32,129] [INFO]: po_5f24457826c0d4641cd2dd35.pdf [in /home/ubuntu/SIH-2020/app/routes.py:515]
[2020-08-01 08:17:32,202] [INFO]: http://3.92.96.170/static/po/po_5f24457826c0d4641cd2dd35.pdf [in /home/ubuntu/SIH-2020/app/routes.py:521]
[2020-08-01 08:17:32,719] [INFO]: <Request 'http://3.92.96.170/api/services/v1/get_po_invoice' [POST]> [in /home/ubuntu/SIH-2020/app/routes.py:503]
[2020-08-01 08:17:32,719] [INFO]: reached po invoice 1 [in /home/ubuntu/SIH-2020/app/routes.py:509]
[2020-08-01 08:17:32,724] [ERROR]: Exception on /api/services/v1/get_po_invoice [POST] [in /home/ubuntu/.local/lib/python3.6/site-packages/flask/app.py:1761]
Traceback (most recent call last):
  File "/home/ubuntu/SIH-2020/app/routes.py", line 512, in get_po_invoice
    content = db.po.find_one({'_id':ObjectId(data['Data']['po_id'])})
KeyError: 'po_id'

During handling of the above exception, another exception occurred:

Traceback (most recent call last):
  File "/home/ubuntu/.local/lib/python3.6/site-packages/flask/app.py", line 2292, in wsgi_app
    response = self.full_dispatch_request()
  File "/home/ubuntu/.local/lib/python3.6/site-packages/flask/app.py", line 1815, in full_dispatch_request
    rv = self.handle_user_exception(e)
  File "/home/ubuntu/.local/lib/python3.6/site-packages/flask/app.py", line 1718, in handle_user_exception
    reraise(exc_type, exc_value, tb)
  File "/home/ubuntu/.local/lib/python3.6/site-packages/flask/_compat.py", line 35, in reraise
    raise value
  File "/home/ubuntu/.local/lib/python3.6/site-packages/flask/app.py", line 1813, in full_dispatch_request
    rv = self.dispatch_request()
  File "/home/ubuntu/.local/lib/python3.6/site-packages/flask/app.py", line 1799, in dispatch_request
    return self.view_functions[rule.endpoint](**req.view_args)
  File "/home/ubuntu/SIH-2020/app/routes.py", line 526, in get_po_invoice
    logger.error(str(e) + "on line no: " + exc_tb.tb_lineno)
NameError: name 'logger' is not defined
[2020-08-01 08:20:38,020] [INFO]: <Request 'http://3.92.96.170/api/services/v1/get_po_invoice' [POST]> [in /home/ubuntu/SIH-2020/app/routes.py:503]
[2020-08-01 08:20:38,020] [INFO]: reached po invoice 1 [in /home/ubuntu/SIH-2020/app/routes.py:509]
[2020-08-01 08:20:38,028] [INFO]: po_5f114408e257dd728e757d66.pdf [in /home/ubuntu/SIH-2020/app/routes.py:515]
[2020-08-01 08:20:38,100] [INFO]: http://3.92.96.170/static/po/po_5f114408e257dd728e757d66.pdf [in /home/ubuntu/SIH-2020/app/routes.py:521]
[2020-08-01 08:20:38,665] [INFO]: <Request 'http://3.92.96.170/api/services/v1/get_po_invoice' [POST]> [in /home/ubuntu/SIH-2020/app/routes.py:503]
[2020-08-01 08:20:38,666] [INFO]: reached po invoice 1 [in /home/ubuntu/SIH-2020/app/routes.py:509]
[2020-08-01 08:20:38,671] [ERROR]: Exception on /api/services/v1/get_po_invoice [POST] [in /home/ubuntu/.local/lib/python3.6/site-packages/flask/app.py:1761]
Traceback (most recent call last):
  File "/home/ubuntu/SIH-2020/app/routes.py", line 512, in get_po_invoice
    content = db.po.find_one({'_id':ObjectId(data['Data']['po_id'])})
KeyError: 'po_id'

During handling of the above exception, another exception occurred:

Traceback (most recent call last):
  File "/home/ubuntu/.local/lib/python3.6/site-packages/flask/app.py", line 2292, in wsgi_app
    response = self.full_dispatch_request()
  File "/home/ubuntu/.local/lib/python3.6/site-packages/flask/app.py", line 1815, in full_dispatch_request
    rv = self.handle_user_exception(e)
  File "/home/ubuntu/.local/lib/python3.6/site-packages/flask/app.py", line 1718, in handle_user_exception
    reraise(exc_type, exc_value, tb)
  File "/home/ubuntu/.local/lib/python3.6/site-packages/flask/_compat.py", line 35, in reraise
    raise value
  File "/home/ubuntu/.local/lib/python3.6/site-packages/flask/app.py", line 1813, in full_dispatch_request
    rv = self.dispatch_request()
  File "/home/ubuntu/.local/lib/python3.6/site-packages/flask/app.py", line 1799, in dispatch_request
    return self.view_functions[rule.endpoint](**req.view_args)
  File "/home/ubuntu/SIH-2020/app/routes.py", line 526, in get_po_invoice
    logger.error(str(e) + "on line no: " + exc_tb.tb_lineno)
NameError: name 'logger' is not defined
[2020-08-01 08:20:48,032] [INFO]: <Request 'http://3.92.96.170/api/services/v1/get_po_invoice' [POST]> [in /home/ubuntu/SIH-2020/app/routes.py:503]
[2020-08-01 08:20:48,033] [INFO]: reached po invoice 1 [in /home/ubuntu/SIH-2020/app/routes.py:509]
[2020-08-01 08:20:48,037] [ERROR]: Exception on /api/services/v1/get_po_invoice [POST] [in /home/ubuntu/.local/lib/python3.6/site-packages/flask/app.py:1761]
Traceback (most recent call last):
  File "/home/ubuntu/SIH-2020/app/routes.py", line 512, in get_po_invoice
    content = db.po.find_one({'_id':ObjectId(data['Data']['po_id'])})
KeyError: 'po_id'

During handling of the above exception, another exception occurred:

Traceback (most recent call last):
  File "/home/ubuntu/.local/lib/python3.6/site-packages/flask/app.py", line 2292, in wsgi_app
    response = self.full_dispatch_request()
  File "/home/ubuntu/.local/lib/python3.6/site-packages/flask/app.py", line 1815, in full_dispatch_request
    rv = self.handle_user_exception(e)
  File "/home/ubuntu/.local/lib/python3.6/site-packages/flask/app.py", line 1718, in handle_user_exception
    reraise(exc_type, exc_value, tb)
  File "/home/ubuntu/.local/lib/python3.6/site-packages/flask/_compat.py", line 35, in reraise
    raise value
  File "/home/ubuntu/.local/lib/python3.6/site-packages/flask/app.py", line 1813, in full_dispatch_request
    rv = self.dispatch_request()
  File "/home/ubuntu/.local/lib/python3.6/site-packages/flask/app.py", line 1799, in dispatch_request
    return self.view_functions[rule.endpoint](**req.view_args)
  File "/home/ubuntu/SIH-2020/app/routes.py", line 526, in get_po_invoice
    logger.error(str(e) + "on line no: " + exc_tb.tb_lineno)
NameError: name 'logger' is not defined
[2020-08-01 08:20:50,999] [INFO]: <Request 'http://3.92.96.170/api/services/v1/get_po_invoice' [POST]> [in /home/ubuntu/SIH-2020/app/routes.py:503]
[2020-08-01 08:20:51,000] [INFO]: reached po invoice 1 [in /home/ubuntu/SIH-2020/app/routes.py:509]
