[2020-07-10 13:44:55,293] [ERROR]: Exception on /index [GET] [in /home/ubuntu/.local/lib/python3.6/site-packages/flask/app.py:1560]
Traceback (most recent call last):
  File "/home/ubuntu/.local/lib/python3.6/site-packages/flask/app.py", line 1982, in wsgi_app
    response = self.full_dispatch_request()
  File "/home/ubuntu/.local/lib/python3.6/site-packages/flask/app.py", line 1614, in full_dispatch_request
    rv = self.handle_user_exception(e)
  File "/home/ubuntu/.local/lib/python3.6/site-packages/flask/app.py", line 1517, in handle_user_exception
    reraise(exc_type, exc_value, tb)
  File "/home/ubuntu/.local/lib/python3.6/site-packages/flask/_compat.py", line 33, in reraise
    raise value
  File "/home/ubuntu/.local/lib/python3.6/site-packages/flask/app.py", line 1612, in full_dispatch_request
    rv = self.dispatch_request()
  File "/home/ubuntu/.local/lib/python3.6/site-packages/flask/app.py", line 1598, in dispatch_request
    return self.view_functions[rule.endpoint](**req.view_args)
  File "/home/ubuntu/.local/lib/python3.6/site-packages/flask_login/utils.py", line 272, in decorated_view
    return func(*args, **kwargs)
  File "/home/ubuntu/SIH-2020/app/routes.py", line 194, in index
    s = s +", " + i
TypeError: must be str, not list
[2020-07-10 13:50:54,060] [INFO]: Supply Chain Startup [in /home/ubuntu/SIH-2020/app/__init__.py:50]
[2020-07-10 13:50:54,115] [INFO]: Supply Chain Startup [in /home/ubuntu/SIH-2020/app/__init__.py:50]
[2020-07-10 13:50:54,181] [INFO]: Supply Chain Startup [in /home/ubuntu/SIH-2020/app/__init__.py:50]
[2020-07-16 16:15:30,846] [INFO]: Supply Chain Startup [in /home/ubuntu/SIH-2020/app/__init__.py:50]
[2020-07-16 16:15:30,857] [INFO]: Supply Chain Startup [in /home/ubuntu/SIH-2020/app/__init__.py:50]
[2020-07-16 16:15:30,969] [INFO]: Supply Chain Startup [in /home/ubuntu/SIH-2020/app/__init__.py:50]
[2020-07-16 16:19:19,164] [INFO]: Supply Chain Startup [in /home/ubuntu/SIH-2020/app/__init__.py:50]
[2020-07-16 16:19:19,219] [INFO]: Supply Chain Startup [in /home/ubuntu/SIH-2020/app/__init__.py:50]
[2020-07-16 16:19:19,268] [INFO]: Supply Chain Startup [in /home/ubuntu/SIH-2020/app/__init__.py:50]
[2020-07-16 16:21:01,314] [ERROR]: Exception on / [GET] [in /usr/local/lib/python3.6/dist-packages/flask/app.py:1560]
Traceback (most recent call last):
  File "/usr/local/lib/python3.6/dist-packages/flask/app.py", line 1982, in wsgi_app
    response = self.full_dispatch_request()
  File "/usr/local/lib/python3.6/dist-packages/flask/app.py", line 1614, in full_dispatch_request
    rv = self.handle_user_exception(e)
  File "/usr/local/lib/python3.6/dist-packages/flask/app.py", line 1517, in handle_user_exception
    reraise(exc_type, exc_value, tb)
  File "/usr/local/lib/python3.6/dist-packages/flask/_compat.py", line 33, in reraise
    raise value
  File "/usr/local/lib/python3.6/dist-packages/flask/app.py", line 1612, in full_dispatch_request
    rv = self.dispatch_request()
  File "/usr/local/lib/python3.6/dist-packages/flask/app.py", line 1598, in dispatch_request
    return self.view_functions[rule.endpoint](**req.view_args)
  File "/home/ubuntu/.local/lib/python3.6/site-packages/flask_login/utils.py", line 272, in decorated_view
    return func(*args, **kwargs)
  File "/home/ubuntu/SIH-2020/app/routes.py", line 193, in index
    for i in own['owned']:
KeyError: 'owned'
[2020-07-16 16:21:05,674] [ERROR]: Exception on / [GET] [in /usr/local/lib/python3.6/dist-packages/flask/app.py:1560]
Traceback (most recent call last):
  File "/usr/local/lib/python3.6/dist-packages/flask/app.py", line 1982, in wsgi_app
    response = self.full_dispatch_request()
  File "/usr/local/lib/python3.6/dist-packages/flask/app.py", line 1614, in full_dispatch_request
    rv = self.handle_user_exception(e)
  File "/usr/local/lib/python3.6/dist-packages/flask/app.py", line 1517, in handle_user_exception
    reraise(exc_type, exc_value, tb)
  File "/usr/local/lib/python3.6/dist-packages/flask/_compat.py", line 33, in reraise
    raise value
  File "/usr/local/lib/python3.6/dist-packages/flask/app.py", line 1612, in full_dispatch_request
    rv = self.dispatch_request()
  File "/usr/local/lib/python3.6/dist-packages/flask/app.py", line 1598, in dispatch_request
    return self.view_functions[rule.endpoint](**req.view_args)
  File "/home/ubuntu/.local/lib/python3.6/site-packages/flask_login/utils.py", line 272, in decorated_view
    return func(*args, **kwargs)
  File "/home/ubuntu/SIH-2020/app/routes.py", line 193, in index
    for i in own['owned']:
KeyError: 'owned'
[2020-07-16 16:21:33,257] [ERROR]: Exception on / [GET] [in /usr/local/lib/python3.6/dist-packages/flask/app.py:1560]
Traceback (most recent call last):
  File "/usr/local/lib/python3.6/dist-packages/flask/app.py", line 1982, in wsgi_app
    response = self.full_dispatch_request()
  File "/usr/local/lib/python3.6/dist-packages/flask/app.py", line 1614, in full_dispatch_request
    rv = self.handle_user_exception(e)
  File "/usr/local/lib/python3.6/dist-packages/flask/app.py", line 1517, in handle_user_exception
    reraise(exc_type, exc_value, tb)
  File "/usr/local/lib/python3.6/dist-packages/flask/_compat.py", line 33, in reraise
    raise value
  File "/usr/local/lib/python3.6/dist-packages/flask/app.py", line 1612, in full_dispatch_request
    rv = self.dispatch_request()
  File "/usr/local/lib/python3.6/dist-packages/flask/app.py", line 1598, in dispatch_request
    return self.view_functions[rule.endpoint](**req.view_args)
  File "/home/ubuntu/.local/lib/python3.6/site-packages/flask_login/utils.py", line 272, in decorated_view
    return func(*args, **kwargs)
  File "/home/ubuntu/SIH-2020/app/routes.py", line 193, in index
    for i in own['owned']:
KeyError: 'owned'
[2020-07-16 16:30:46,198] [INFO]: Supply Chain Startup [in /home/ubuntu/SIH-2020/app/__init__.py:50]
[2020-07-16 16:30:46,221] [INFO]: Supply Chain Startup [in /home/ubuntu/SIH-2020/app/__init__.py:50]
[2020-07-16 16:30:46,286] [INFO]: Supply Chain Startup [in /home/ubuntu/SIH-2020/app/__init__.py:50]
[2020-07-16 17:25:08,109] [INFO]: {'provider': 'username', 'Data': {'serial_no': 'bis1'}} [in /home/ubuntu/SIH-2020/app/routes.py:814]
[2020-07-16 17:37:06,241] [INFO]: {'provider': 'username', 'Data': {'serial_no': 'cjx bvjdbjvdnvvdndvmn,vmnjjkdkjdkjdksjvkbjkbjkdkbkdfhkdsjhkdhskdshdskhdskhvkvdkkdkdhbhdjbhdkhbkbhdkhkbfhkfhfkfhkfhfhh'}} [in /home/ubuntu/SIH-2020/app/routes.py:814]
[2020-07-16 17:38:43,466] [INFO]: {'provider': 'username', 'Data': {'serial_no': 'bis1'}} [in /home/ubuntu/SIH-2020/app/routes.py:814]
[2020-07-16 17:51:30,686] [INFO]: {'provider': 'username', 'Data': {'serial_no': 'exp://192.168.0.106:19000'}} [in /home/ubuntu/SIH-2020/app/routes.py:814]
[2020-07-16 17:58:08,430] [INFO]: {'provider': 'username', 'Data': {'serial_no': 'bis1'}} [in /home/ubuntu/SIH-2020/app/routes.py:814]
[2020-07-16 18:06:33,075] [INFO]: {'provider': 'username', 'Data': {'serial_no': 'bis1'}} [in /home/ubuntu/SIH-2020/app/routes.py:814]
[2020-07-16 18:08:12,585] [INFO]: {'provider': 'username', 'Data': {'serial_no': 'bis1'}} [in /home/ubuntu/SIH-2020/app/routes.py:814]
[2020-07-16 18:14:23,990] [INFO]: {'provider': 'username', 'Data': {'serial_no': 'bis1'}} [in /home/ubuntu/SIH-2020/app/routes.py:814]
[2020-07-16 18:15:56,681] [INFO]: {'provider': 'username', 'Data': {'serial_no': 'bis1'}} [in /home/ubuntu/SIH-2020/app/routes.py:814]
[2020-07-16 18:16:11,325] [INFO]: {'provider': 'username', 'Data': {'serial_no': 'bis1'}} [in /home/ubuntu/SIH-2020/app/routes.py:814]
[2020-07-16 18:16:27,709] [INFO]: {'provider': 'username', 'Data': {'serial_no': 'abc2'}} [in /home/ubuntu/SIH-2020/app/routes.py:814]
[2020-07-16 18:37:42,352] [INFO]: {'provider': 'username', 'Data': {'serial_no': 'bis1'}} [in /home/ubuntu/SIH-2020/app/routes.py:814]
[2020-07-16 18:38:03,519] [INFO]: {'provider': 'username', 'Data': {'serial_no': 'bis1'}} [in /home/ubuntu/SIH-2020/app/routes.py:814]
[2020-07-16 18:39:19,620] [INFO]: {'provider': 'username', 'Data': {'serial_no': 'bis1'}} [in /home/ubuntu/SIH-2020/app/routes.py:814]
[2020-07-16 18:41:14,492] [INFO]: {'provider': 'username', 'Data': {'serial_no': 'bis1'}} [in /home/ubuntu/SIH-2020/app/routes.py:814]
[2020-07-16 18:44:00,526] [INFO]: {'provider': 'username', 'Data': {'serial_no': 'bis1'}} [in /home/ubuntu/SIH-2020/app/routes.py:814]
[2020-07-16 18:46:56,319] [INFO]: {'provider': 'username', 'Data': {'serial_no': 'bis1'}} [in /home/ubuntu/SIH-2020/app/routes.py:814]
[2020-07-16 18:47:05,686] [INFO]: {'provider': 'username', 'Data': {'serial_no': 'bis1'}} [in /home/ubuntu/SIH-2020/app/routes.py:814]
[2020-07-16 18:52:28,305] [INFO]: {'provider': 'username', 'Data': {'serial_no': 'bis1'}} [in /home/ubuntu/SIH-2020/app/routes.py:814]
[2020-07-16 19:36:20,053] [INFO]: Supply Chain Startup [in /home/ubuntu/SIH-2020/app/__init__.py:54]
[2020-07-16 19:36:20,121] [INFO]: Supply Chain Startup [in /home/ubuntu/SIH-2020/app/__init__.py:54]
[2020-07-16 19:36:20,234] [INFO]: Supply Chain Startup [in /home/ubuntu/SIH-2020/app/__init__.py:54]
[2020-07-16 19:40:03,950] [ERROR]: Unhandled exception [in /home/ubuntu/SIH-2020/app/tasks.py:70]
Traceback (most recent call last):
  File "/home/ubuntu/SIH-2020/app/tasks.py", line 67, in transfer_asset_async
    username,serial_no,priv_key,no,assets[temp:])
  File "/home/ubuntu/SIH-2020/app/models.py", line 15, in launch_task
    app.logger.info("Task queue")
NameError: name 'app' is not defined
[2020-07-17 05:39:36,082] [INFO]: Supply Chain Startup [in /home/ubuntu/SIH-2020/app/__init__.py:54]
[2020-07-17 05:39:36,104] [INFO]: Supply Chain Startup [in /home/ubuntu/SIH-2020/app/__init__.py:54]
[2020-07-17 05:39:36,114] [INFO]: Supply Chain Startup [in /home/ubuntu/SIH-2020/app/__init__.py:54]
