[2020-07-31 15:33:51,573] [ERROR]: Exception on /api/services/v1/get_po_invoice [POST] [in /usr/local/lib/python3.6/dist-packages/flask/app.py:1560]
Traceback (most recent call last):
  File "/home/ubuntu/SIH-2020/app/routes.py", line 514, in get_po_invoice
    content = db.po.find_one({'_id':ObjectId(data['Data']['po_id'])})
KeyError: 'po_id'

During handling of the above exception, another exception occurred:

Traceback (most recent call last):
  File "/usr/local/lib/python3.6/dist-packages/flask/app.py", line 1982, in wsgi_app
    response = self.full_dispatch_request()
  File "/usr/local/lib/python3.6/dist-packages/flask/app.py", line 1614, in full_dispatch_request
    rv = self.handle_user_exception(e)
  File "/usr/local/lib/python3.6/dist-packages/flask/app.py", line 1517, in handle_user_exception
    reraise(exc_type, exc_value, tb)
  File "/usr/local/lib/python3.6/dist-packages/flask/_compat.py", line 33, in reraise
    raise value
  File "/usr/local/lib/python3.6/dist-packages/flask/app.py", line 1612, in full_dispatch_request
    rv = self.dispatch_request()
  File "/usr/local/lib/python3.6/dist-packages/flask/app.py", line 1598, in dispatch_request
    return self.view_functions[rule.endpoint](**req.view_args)
  File "/home/ubuntu/SIH-2020/app/routes.py", line 528, in get_po_invoice
    logger.error(str(e) + "on line no: " + exc_tb.tb_lineno)
NameError: name 'logger' is not defined
[2020-07-31 15:33:51,979] [INFO]: <Request 'http://3.215.183.155/api/services/v1/get_po_invoice' [POST]> [in /home/ubuntu/SIH-2020/app/routes.py:505]
[2020-07-31 15:33:51,979] [INFO]: reached po invoice 1 [in /home/ubuntu/SIH-2020/app/routes.py:511]
[2020-07-31 15:33:52,678] [INFO]: po_5f114408e257dd728e757d66.pdf [in /home/ubuntu/SIH-2020/app/routes.py:517]
[2020-07-31 15:33:52,753] [INFO]: http://3.215.183.155/static/po/po_5f114408e257dd728e757d66.pdf [in /home/ubuntu/SIH-2020/app/routes.py:523]
[2020-07-31 15:33:54,345] [INFO]: <Request 'http://3.215.183.155/api/services/v1/get_po_invoice' [POST]> [in /home/ubuntu/SIH-2020/app/routes.py:505]
[2020-07-31 15:33:54,346] [INFO]: reached po invoice 1 [in /home/ubuntu/SIH-2020/app/routes.py:511]
[2020-07-31 15:33:54,351] [ERROR]: Exception on /api/services/v1/get_po_invoice [POST] [in /usr/local/lib/python3.6/dist-packages/flask/app.py:1560]
Traceback (most recent call last):
  File "/home/ubuntu/SIH-2020/app/routes.py", line 514, in get_po_invoice
    content = db.po.find_one({'_id':ObjectId(data['Data']['po_id'])})
KeyError: 'po_id'

During handling of the above exception, another exception occurred:

Traceback (most recent call last):
  File "/usr/local/lib/python3.6/dist-packages/flask/app.py", line 1982, in wsgi_app
    response = self.full_dispatch_request()
  File "/usr/local/lib/python3.6/dist-packages/flask/app.py", line 1614, in full_dispatch_request
    rv = self.handle_user_exception(e)
  File "/usr/local/lib/python3.6/dist-packages/flask/app.py", line 1517, in handle_user_exception
    reraise(exc_type, exc_value, tb)
  File "/usr/local/lib/python3.6/dist-packages/flask/_compat.py", line 33, in reraise
    raise value
  File "/usr/local/lib/python3.6/dist-packages/flask/app.py", line 1612, in full_dispatch_request
    rv = self.dispatch_request()
  File "/usr/local/lib/python3.6/dist-packages/flask/app.py", line 1598, in dispatch_request
    return self.view_functions[rule.endpoint](**req.view_args)
  File "/home/ubuntu/SIH-2020/app/routes.py", line 528, in get_po_invoice
    logger.error(str(e) + "on line no: " + exc_tb.tb_lineno)
NameError: name 'logger' is not defined
[2020-07-31 15:34:04,090] [INFO]: <Request 'http://3.215.183.155/api/services/v1/get_po_invoice' [POST]> [in /home/ubuntu/SIH-2020/app/routes.py:505]
[2020-07-31 15:34:04,091] [INFO]: reached po invoice 1 [in /home/ubuntu/SIH-2020/app/routes.py:511]
[2020-07-31 15:34:04,098] [INFO]: po_5f157208ea95723b48ff59f7.pdf [in /home/ubuntu/SIH-2020/app/routes.py:517]
[2020-07-31 15:34:04,169] [INFO]: http://3.215.183.155/static/po/po_5f157208ea95723b48ff59f7.pdf [in /home/ubuntu/SIH-2020/app/routes.py:523]
[2020-07-31 15:36:31,094] [INFO]: {'provider': 'username', 'Data': {'serial_no': ' '}} [in /home/ubuntu/SIH-2020/app/routes.py:995]
[2020-07-31 15:36:31,242] [INFO]: {'provider': 'username', 'Data': {'serial_no': ' '}} [in /home/ubuntu/SIH-2020/app/routes.py:995]
[2020-07-31 16:25:02,457] [INFO]: Inside get asset api [in /home/ubuntu/SIH-2020/app/routes.py:930]
[2020-07-31 16:25:02,457] [INFO]: {'provider': 'username', 'Data': {'username': 'manav_broker'}} [in /home/ubuntu/SIH-2020/app/routes.py:933]
[2020-07-31 16:29:27,890] [INFO]: {'provider': 'username', 'Data': {'serial_no': 'PUCT8DkJNpU8vxgkALJGqd'}} [in /home/ubuntu/SIH-2020/app/routes.py:995]
[2020-07-31 16:30:39,645] [INFO]: Inside get asset api [in /home/ubuntu/SIH-2020/app/routes.py:930]
[2020-07-31 16:30:39,646] [INFO]: {'provider': 'username', 'Data': {'username': 'manav_broker'}} [in /home/ubuntu/SIH-2020/app/routes.py:933]
[2020-07-31 16:32:03,346] [INFO]: {'provider': 'username', 'Data': {'serial_no': ' '}} [in /home/ubuntu/SIH-2020/app/routes.py:995]
[2020-07-31 16:32:03,469] [INFO]: {'provider': 'username', 'Data': {'serial_no': ' '}} [in /home/ubuntu/SIH-2020/app/routes.py:995]
[2020-07-31 16:33:05,788] [INFO]: {'provider': 'username', 'Data': {'serial_no': ' '}} [in /home/ubuntu/SIH-2020/app/routes.py:995]
[2020-07-31 16:33:31,601] [INFO]: {'provider': 'username', 'Data': {'serial_no': ' bis1'}} [in /home/ubuntu/SIH-2020/app/routes.py:995]
[2020-07-31 16:33:58,043] [INFO]: {'provider': 'username', 'Data': {'serial_no': ' '}} [in /home/ubuntu/SIH-2020/app/routes.py:995]
[2020-07-31 16:34:23,902] [INFO]: {'provider': 'username', 'Data': {'serial_no': ' '}} [in /home/ubuntu/SIH-2020/app/routes.py:995]
[2020-07-31 16:35:14,958] [INFO]: {'provider': 'username', 'Data': {'serial_no': ' '}} [in /home/ubuntu/SIH-2020/app/routes.py:995]
[2020-07-31 16:36:46,533] [INFO]: {'provider': 'username', 'Data': {'serial_no': ' '}} [in /home/ubuntu/SIH-2020/app/routes.py:995]
[2020-07-31 16:36:46,663] [INFO]: {'provider': 'username', 'Data': {'serial_no': ' '}} [in /home/ubuntu/SIH-2020/app/routes.py:995]
[2020-07-31 16:38:17,905] [INFO]: {'provider': 'username', 'Data': {'serial_no': ' '}} [in /home/ubuntu/SIH-2020/app/routes.py:995]
[2020-07-31 16:38:17,999] [INFO]: {'provider': 'username', 'Data': {'serial_no': ' '}} [in /home/ubuntu/SIH-2020/app/routes.py:995]
[2020-07-31 16:38:23,180] [INFO]: {'provider': 'username', 'Data': {'serial_no': 'bis1'}} [in /home/ubuntu/SIH-2020/app/routes.py:995]
[2020-07-31 16:39:25,945] [INFO]: {'provider': 'username', 'Data': {'serial_no': ' '}} [in /home/ubuntu/SIH-2020/app/routes.py:995]
[2020-07-31 16:41:44,908] [INFO]: {'provider': 'username', 'Data': {'serial_no': ' '}} [in /home/ubuntu/SIH-2020/app/routes.py:995]
[2020-07-31 16:41:45,193] [INFO]: {'provider': 'username', 'Data': {'serial_no': ' '}} [in /home/ubuntu/SIH-2020/app/routes.py:995]
[2020-07-31 16:42:08,602] [INFO]: {'provider': 'username', 'Data': {'serial_no': ' bis1'}} [in /home/ubuntu/SIH-2020/app/routes.py:995]
[2020-07-31 18:20:45,013] [INFO]: {'provider': 'username', 'Data': {'serial_no': ' '}} [in /home/ubuntu/SIH-2020/app/routes.py:995]
[2020-07-31 18:25:40,921] [INFO]: {'provider': 'username', 'Data': {'serial_no': ' '}} [in /home/ubuntu/SIH-2020/app/routes.py:995]
[2020-07-31 18:26:37,397] [INFO]: {'provider': 'username', 'Data': {'serial_no': 'PUCT8DkJNpU8vxgkALJGqd'}} [in /home/ubuntu/SIH-2020/app/routes.py:995]
[2020-07-31 18:28:50,407] [INFO]: <Request 'http://3.215.183.155/api/services/v1/get_po_invoice' [POST]> [in /home/ubuntu/SIH-2020/app/routes.py:505]
[2020-07-31 18:28:50,408] [INFO]: reached po invoice 1 [in /home/ubuntu/SIH-2020/app/routes.py:511]
[2020-07-31 18:28:50,415] [INFO]: po_5f114408e257dd728e757d66.pdf [in /home/ubuntu/SIH-2020/app/routes.py:517]
[2020-07-31 18:28:50,487] [INFO]: http://3.215.183.155/static/po/po_5f114408e257dd728e757d66.pdf [in /home/ubuntu/SIH-2020/app/routes.py:523]
[2020-07-31 19:44:46,719] [INFO]: {'provider': 'username', 'Data': {'serial_no': ' '}} [in /home/ubuntu/SIH-2020/app/routes.py:995]
[2020-08-01 03:06:35,891] [INFO]: {'provider': 'username', 'Data': {'serial_no': ' '}} [in /home/ubuntu/SIH-2020/app/routes.py:995]
[2020-08-01 03:06:35,974] [INFO]: {'provider': 'username', 'Data': {'serial_no': ' '}} [in /home/ubuntu/SIH-2020/app/routes.py:995]
[2020-08-01 12:56:49,406] [INFO]: {'provider': 'username', 'Data': {'serial_no': 'PUCT8DkJNpU8vxgkALJGqd'}} [in /home/ubuntu/SIH-2020/app/routes.py:995]
[2020-08-01 12:56:49,450] [INFO]: {'provider': 'username', 'Data': {'serial_no': 'PUCT8DkJNpU8vxgkALJGqd'}} [in /home/ubuntu/SIH-2020/app/routes.py:995]
[2020-08-01 16:47:13,266] [INFO]: {'provider': 'username', 'Data': {'serial_no': ' '}} [in /home/ubuntu/SIH-2020/app/routes.py:995]
[2020-08-01 16:48:06,086] [INFO]: {'provider': 'username', 'Data': {'serial_no': 'PUCT8DkJNpU8vxgkALJGqd'}} [in /home/ubuntu/SIH-2020/app/routes.py:995]
[2020-08-01 16:58:00,507] [INFO]: <Request 'http://3.215.183.155/api/services/v1/get_po_invoice' [POST]> [in /home/ubuntu/SIH-2020/app/routes.py:505]
[2020-08-01 16:58:00,507] [INFO]: reached po invoice 1 [in /home/ubuntu/SIH-2020/app/routes.py:511]
