[2020-07-31 15:27:58,887] [INFO]: http://3.215.183.155/static/po/po_5f109c3589d2b31d78a53343.pdf [in /home/ubuntu/SIH-2020/app/routes.py:523]
[2020-07-31 15:34:05,328] [INFO]: <Request 'http://3.215.183.155/api/services/v1/get_po_invoice' [POST]> [in /home/ubuntu/SIH-2020/app/routes.py:505]
[2020-07-31 15:34:05,329] [INFO]: reached po invoice 1 [in /home/ubuntu/SIH-2020/app/routes.py:511]
[2020-07-31 15:34:05,334] [ERROR]: Exception on /api/services/v1/get_po_invoice [POST] [in /usr/local/lib/python3.6/dist-packages/flask/app.py:1560]
Traceback (most recent call last):
  File "/home/ubuntu/SIH-2020/app/routes.py", line 514, in get_po_invoice
    content = db.po.find_one({'_id':ObjectId(data['Data']['po_id'])})
KeyError: 'po_id'

During handling of the above exception, another exception occurred:

Traceback (most recent call last):
  File "/usr/local/lib/python3.6/dist-packages/flask/app.py", line 1982, in wsgi_app
    response = self.full_dispatch_request()
  File "/usr/local/lib/python3.6/dist-packages/flask/app.py", line 1614, in full_dispatch_request
    rv = self.handle_user_exception(e)
  File "/usr/local/lib/python3.6/dist-packages/flask/app.py", line 1517, in handle_user_exception
    reraise(exc_type, exc_value, tb)
  File "/usr/local/lib/python3.6/dist-packages/flask/_compat.py", line 33, in reraise
    raise value
  File "/usr/local/lib/python3.6/dist-packages/flask/app.py", line 1612, in full_dispatch_request
    rv = self.dispatch_request()
  File "/usr/local/lib/python3.6/dist-packages/flask/app.py", line 1598, in dispatch_request
    return self.view_functions[rule.endpoint](**req.view_args)
  File "/home/ubuntu/SIH-2020/app/routes.py", line 528, in get_po_invoice
    logger.error(str(e) + "on line no: " + exc_tb.tb_lineno)
NameError: name 'logger' is not defined
[2020-07-31 16:29:16,850] [INFO]: {'provider': 'username', 'Data': {'serial_no': ' '}} [in /home/ubuntu/SIH-2020/app/routes.py:995]
[2020-07-31 16:29:16,980] [INFO]: {'provider': 'username', 'Data': {'serial_no': ' '}} [in /home/ubuntu/SIH-2020/app/routes.py:995]
[2020-07-31 16:29:22,763] [INFO]: {'provider': 'username', 'Data': {'serial_no': '2o76GcYaPSwMXFJd6wQsJX'}} [in /home/ubuntu/SIH-2020/app/routes.py:995]
[2020-07-31 16:30:06,451] [INFO]: {'provider': 'username', 'Data': {'serial_no': '7zWdffH5DsiaUAbrPsKj2X'}} [in /home/ubuntu/SIH-2020/app/routes.py:995]
[2020-07-31 16:30:06,619] [INFO]: {'provider': 'username', 'Data': {'serial_no': '7zWdffH5DsiaUAbrPsKj2X'}} [in /home/ubuntu/SIH-2020/app/routes.py:995]
[2020-07-31 16:30:18,354] [INFO]: {'provider': 'username', 'Data': {'serial_no': 'nDdSyk5aBKvVwZzvtaBdwp'}} [in /home/ubuntu/SIH-2020/app/routes.py:995]
[2020-07-31 16:30:26,529] [INFO]: {'provider': 'username', 'Data': {'serial_no': 'MXYXBeeeDKuxfRTvZHKXjD'}} [in /home/ubuntu/SIH-2020/app/routes.py:995]
[2020-07-31 16:32:42,259] [INFO]: {'provider': 'username', 'Data': {'serial_no': ' bis1'}} [in /home/ubuntu/SIH-2020/app/routes.py:995]
[2020-07-31 16:33:53,076] [INFO]: {'provider': 'username', 'Data': {'serial_no': ' '}} [in /home/ubuntu/SIH-2020/app/routes.py:995]
[2020-07-31 16:33:57,693] [INFO]: {'provider': 'username', 'Data': {'serial_no': ' '}} [in /home/ubuntu/SIH-2020/app/routes.py:995]
[2020-07-31 16:34:42,494] [INFO]: {'provider': 'username', 'Data': {'serial_no': ' bis1'}} [in /home/ubuntu/SIH-2020/app/routes.py:995]
[2020-07-31 16:35:07,443] [INFO]: {'provider': 'username', 'Data': {'serial_no': ' '}} [in /home/ubuntu/SIH-2020/app/routes.py:995]
[2020-07-31 16:35:07,792] [INFO]: {'provider': 'username', 'Data': {'serial_no': ' '}} [in /home/ubuntu/SIH-2020/app/routes.py:995]
[2020-07-31 16:35:15,133] [INFO]: {'provider': 'username', 'Data': {'serial_no': ' '}} [in /home/ubuntu/SIH-2020/app/routes.py:995]
[2020-07-31 16:40:15,226] [INFO]: {'provider': 'username', 'Data': {'serial_no': ' '}} [in /home/ubuntu/SIH-2020/app/routes.py:995]
[2020-07-31 16:41:37,659] [INFO]: {'provider': 'username', 'Data': {'serial_no': ' '}} [in /home/ubuntu/SIH-2020/app/routes.py:995]
[2020-07-31 16:41:37,773] [INFO]: {'provider': 'username', 'Data': {'serial_no': ' '}} [in /home/ubuntu/SIH-2020/app/routes.py:995]
[2020-07-31 18:27:08,967] [INFO]: {'provider': 'username', 'Data': {'serial_no': ' '}} [in /home/ubuntu/SIH-2020/app/routes.py:995]
[2020-07-31 18:28:54,229] [INFO]: <Request 'http://3.215.183.155/api/services/v1/get_po_invoice' [POST]> [in /home/ubuntu/SIH-2020/app/routes.py:505]
[2020-07-31 18:28:54,230] [INFO]: reached po invoice 1 [in /home/ubuntu/SIH-2020/app/routes.py:511]
[2020-07-31 18:28:54,237] [INFO]: po_5f157208ea95723b48ff59f7.pdf [in /home/ubuntu/SIH-2020/app/routes.py:517]
[2020-07-31 18:28:54,310] [INFO]: http://3.215.183.155/static/po/po_5f157208ea95723b48ff59f7.pdf [in /home/ubuntu/SIH-2020/app/routes.py:523]
[2020-07-31 18:28:54,774] [INFO]: <Request 'http://3.215.183.155/api/services/v1/get_po_invoice' [POST]> [in /home/ubuntu/SIH-2020/app/routes.py:505]
[2020-07-31 18:28:54,775] [INFO]: reached po invoice 1 [in /home/ubuntu/SIH-2020/app/routes.py:511]
[2020-07-31 18:28:54,780] [ERROR]: Exception on /api/services/v1/get_po_invoice [POST] [in /usr/local/lib/python3.6/dist-packages/flask/app.py:1560]
Traceback (most recent call last):
  File "/home/ubuntu/SIH-2020/app/routes.py", line 514, in get_po_invoice
    content = db.po.find_one({'_id':ObjectId(data['Data']['po_id'])})
KeyError: 'po_id'

During handling of the above exception, another exception occurred:

Traceback (most recent call last):
  File "/usr/local/lib/python3.6/dist-packages/flask/app.py", line 1982, in wsgi_app
    response = self.full_dispatch_request()
  File "/usr/local/lib/python3.6/dist-packages/flask/app.py", line 1614, in full_dispatch_request
    rv = self.handle_user_exception(e)
  File "/usr/local/lib/python3.6/dist-packages/flask/app.py", line 1517, in handle_user_exception
    reraise(exc_type, exc_value, tb)
  File "/usr/local/lib/python3.6/dist-packages/flask/_compat.py", line 33, in reraise
    raise value
  File "/usr/local/lib/python3.6/dist-packages/flask/app.py", line 1612, in full_dispatch_request
    rv = self.dispatch_request()
  File "/usr/local/lib/python3.6/dist-packages/flask/app.py", line 1598, in dispatch_request
    return self.view_functions[rule.endpoint](**req.view_args)
  File "/home/ubuntu/SIH-2020/app/routes.py", line 528, in get_po_invoice
    logger.error(str(e) + "on line no: " + exc_tb.tb_lineno)
NameError: name 'logger' is not defined
[2020-07-31 18:31:02,285] [INFO]: {'provider': 'username', 'Data': {'serial_no': ' '}} [in /home/ubuntu/SIH-2020/app/routes.py:995]
[2020-08-01 16:47:13,410] [INFO]: {'provider': 'username', 'Data': {'serial_no': ' '}} [in /home/ubuntu/SIH-2020/app/routes.py:995]
[2020-08-01 16:47:19,443] [INFO]: {'provider': 'username', 'Data': {'serial_no': ' bis1'}} [in /home/ubuntu/SIH-2020/app/routes.py:995]
[2020-08-01 16:47:53,055] [INFO]: {'provider': 'username', 'Data': {'serial_no': ' '}} [in /home/ubuntu/SIH-2020/app/routes.py:995]
[2020-08-01 16:47:58,981] [INFO]: {'provider': 'username', 'Data': {'serial_no': 'bis1'}} [in /home/ubuntu/SIH-2020/app/routes.py:995]
[2020-08-01 16:48:09,627] [INFO]: {'provider': 'username', 'Data': {'serial_no': 'bis1'}} [in /home/ubuntu/SIH-2020/app/routes.py:995]
[2020-08-01 16:56:24,418] [INFO]: {'provider': 'username', 'Data': {'serial_no': ' '}} [in /home/ubuntu/SIH-2020/app/routes.py:995]
[2020-08-01 16:57:40,040] [INFO]: <Request 'http://3.215.183.155/api/services/v1/get_po_invoice' [POST]> [in /home/ubuntu/SIH-2020/app/routes.py:505]
[2020-08-01 16:57:40,040] [INFO]: reached po invoice 1 [in /home/ubuntu/SIH-2020/app/routes.py:511]
[2020-08-01 16:57:40,048] [INFO]: po_5f114408e257dd728e757d66.pdf [in /home/ubuntu/SIH-2020/app/routes.py:517]
[2020-08-01 16:57:40,123] [INFO]: http://3.215.183.155/static/po/po_5f114408e257dd728e757d66.pdf [in /home/ubuntu/SIH-2020/app/routes.py:523]
[2020-08-01 16:57:59,083] [INFO]: <Request 'http://3.215.183.155/api/services/v1/get_po_invoice' [POST]> [in /home/ubuntu/SIH-2020/app/routes.py:505]
[2020-08-01 16:57:59,083] [INFO]: reached po invoice 1 [in /home/ubuntu/SIH-2020/app/routes.py:511]
[2020-08-01 16:57:59,091] [INFO]: po_5f114408e257dd728e757d66.pdf [in /home/ubuntu/SIH-2020/app/routes.py:517]
[2020-08-01 16:57:59,165] [INFO]: http://3.215.183.155/static/po/po_5f114408e257dd728e757d66.pdf [in /home/ubuntu/SIH-2020/app/routes.py:523]
[2020-08-01 16:58:44,209] [INFO]: <Request 'http://3.215.183.155/api/services/v1/get_po_invoice' [POST]> [in /home/ubuntu/SIH-2020/app/routes.py:505]
[2020-08-01 16:58:44,210] [INFO]: reached po invoice 1 [in /home/ubuntu/SIH-2020/app/routes.py:511]
[2020-08-01 16:58:44,218] [INFO]: po_5f114408e257dd728e757d66.pdf [in /home/ubuntu/SIH-2020/app/routes.py:517]
[2020-08-01 16:58:44,291] [INFO]: http://3.215.183.155/static/po/po_5f114408e257dd728e757d66.pdf [in /home/ubuntu/SIH-2020/app/routes.py:523]
[2020-08-01 18:00:41,394] [INFO]: {'provider': 'username', 'Data': {'serial_no': ' '}} [in /home/ubuntu/SIH-2020/app/routes.py:995]
[2020-08-01 18:00:41,666] [INFO]: {'provider': 'username', 'Data': {'serial_no': ' '}} [in /home/ubuntu/SIH-2020/app/routes.py:995]
[2020-08-01 18:00:55,445] [INFO]: {'provider': 'username', 'Data': {'serial_no': '2o76GcYaPSwMXFJd6wQsJX'}} [in /home/ubuntu/SIH-2020/app/routes.py:995]
[2020-08-01 18:02:16,643] [INFO]: {'provider': 'username', 'Data': {'serial_no': ' bis1'}} [in /home/ubuntu/SIH-2020/app/routes.py:995]
[2020-08-01 18:23:58,762] [INFO]: {'provider': 'username', 'Data': {'serial_no': ' '}} [in /home/ubuntu/SIH-2020/app/routes.py:995]
[2020-08-01 18:24:25,124] [INFO]: {'provider': 'username', 'Data': {'serial_no': ' '}} [in /home/ubuntu/SIH-2020/app/routes.py:995]
[2020-08-01 18:27:50,828] [INFO]: {'provider': 'username', 'Data': {'serial_no': 'bis1'}} [in /home/ubuntu/SIH-2020/app/routes.py:995]
[2020-08-01 18:28:08,948] [INFO]: {'provider': 'username', 'Data': {'serial_no': 'bis1'}} [in /home/ubuntu/SIH-2020/app/routes.py:995]
[2020-08-01 18:42:39,349] [INFO]: {'provider': 'username', 'Data': {'serial_no': ' '}} [in /home/ubuntu/SIH-2020/app/routes.py:995]
