[2020-07-31 13:25:01,440] [INFO]: {'provider': 'username', 'Data': {'serial_no': 'cUQWnX8AKYHmSPRo8Vegdk'}} [in /home/ubuntu/SIH-2020/app/routes.py:995]
[2020-07-31 13:28:40,972] [INFO]: {'provider': 'username', 'Data': {'serial_no': 'HdYeoJosgKww7u7cG2zWUv'}} [in /home/ubuntu/SIH-2020/app/routes.py:995]
[2020-07-31 13:29:29,987] [INFO]: <Request 'http://3.215.183.155/api/services/v1/get_po_invoice' [POST]> [in /home/ubuntu/SIH-2020/app/routes.py:505]
[2020-07-31 13:29:29,988] [INFO]: reached po invoice 1 [in /home/ubuntu/SIH-2020/app/routes.py:511]
[2020-07-31 13:29:29,995] [INFO]: po_5f157208ea95723b48ff59f7.pdf [in /home/ubuntu/SIH-2020/app/routes.py:517]
[2020-07-31 13:29:30,088] [INFO]: http://3.215.183.155/static/po/po_5f157208ea95723b48ff59f7.pdf [in /home/ubuntu/SIH-2020/app/routes.py:523]
[2020-07-31 13:29:31,076] [INFO]: <Request 'http://3.215.183.155/api/services/v1/get_po_invoice' [POST]> [in /home/ubuntu/SIH-2020/app/routes.py:505]
[2020-07-31 13:29:31,077] [INFO]: reached po invoice 1 [in /home/ubuntu/SIH-2020/app/routes.py:511]
[2020-07-31 13:29:31,082] [ERROR]: Exception on /api/services/v1/get_po_invoice [POST] [in /usr/local/lib/python3.6/dist-packages/flask/app.py:1560]
Traceback (most recent call last):
  File "/home/ubuntu/SIH-2020/app/routes.py", line 514, in get_po_invoice
    content = db.po.find_one({'_id':ObjectId(data['Data']['po_id'])})
KeyError: 'po_id'

During handling of the above exception, another exception occurred:

Traceback (most recent call last):
  File "/usr/local/lib/python3.6/dist-packages/flask/app.py", line 1982, in wsgi_app
    response = self.full_dispatch_request()
  File "/usr/local/lib/python3.6/dist-packages/flask/app.py", line 1614, in full_dispatch_request
    rv = self.handle_user_exception(e)
  File "/usr/local/lib/python3.6/dist-packages/flask/app.py", line 1517, in handle_user_exception
    reraise(exc_type, exc_value, tb)
  File "/usr/local/lib/python3.6/dist-packages/flask/_compat.py", line 33, in reraise
    raise value
  File "/usr/local/lib/python3.6/dist-packages/flask/app.py", line 1612, in full_dispatch_request
    rv = self.dispatch_request()
  File "/usr/local/lib/python3.6/dist-packages/flask/app.py", line 1598, in dispatch_request
    return self.view_functions[rule.endpoint](**req.view_args)
  File "/home/ubuntu/SIH-2020/app/routes.py", line 528, in get_po_invoice
    logger.error(str(e) + "on line no: " + exc_tb.tb_lineno)
NameError: name 'logger' is not defined
[2020-07-31 13:29:46,455] [INFO]: <Request 'http://3.215.183.155/api/services/v1/get_po_invoice' [POST]> [in /home/ubuntu/SIH-2020/app/routes.py:505]
[2020-07-31 13:29:46,455] [INFO]: reached po invoice 1 [in /home/ubuntu/SIH-2020/app/routes.py:511]
[2020-07-31 13:29:46,460] [ERROR]: Exception on /api/services/v1/get_po_invoice [POST] [in /usr/local/lib/python3.6/dist-packages/flask/app.py:1560]
Traceback (most recent call last):
  File "/home/ubuntu/SIH-2020/app/routes.py", line 514, in get_po_invoice
    content = db.po.find_one({'_id':ObjectId(data['Data']['po_id'])})
KeyError: 'po_id'

During handling of the above exception, another exception occurred:

Traceback (most recent call last):
  File "/usr/local/lib/python3.6/dist-packages/flask/app.py", line 1982, in wsgi_app
    response = self.full_dispatch_request()
  File "/usr/local/lib/python3.6/dist-packages/flask/app.py", line 1614, in full_dispatch_request
    rv = self.handle_user_exception(e)
  File "/usr/local/lib/python3.6/dist-packages/flask/app.py", line 1517, in handle_user_exception
    reraise(exc_type, exc_value, tb)
  File "/usr/local/lib/python3.6/dist-packages/flask/_compat.py", line 33, in reraise
    raise value
  File "/usr/local/lib/python3.6/dist-packages/flask/app.py", line 1612, in full_dispatch_request
    rv = self.dispatch_request()
  File "/usr/local/lib/python3.6/dist-packages/flask/app.py", line 1598, in dispatch_request
    return self.view_functions[rule.endpoint](**req.view_args)
  File "/home/ubuntu/SIH-2020/app/routes.py", line 528, in get_po_invoice
    logger.error(str(e) + "on line no: " + exc_tb.tb_lineno)
NameError: name 'logger' is not defined
[2020-07-31 13:30:25,196] [INFO]: <Request 'http://3.215.183.155/api/services/v1/get_po_invoice' [POST]> [in /home/ubuntu/SIH-2020/app/routes.py:505]
[2020-07-31 13:30:25,196] [INFO]: reached po invoice 1 [in /home/ubuntu/SIH-2020/app/routes.py:511]
[2020-07-31 13:30:25,201] [ERROR]: Exception on /api/services/v1/get_po_invoice [POST] [in /usr/local/lib/python3.6/dist-packages/flask/app.py:1560]
Traceback (most recent call last):
  File "/home/ubuntu/SIH-2020/app/routes.py", line 514, in get_po_invoice
    content = db.po.find_one({'_id':ObjectId(data['Data']['po_id'])})
KeyError: 'po_id'

During handling of the above exception, another exception occurred:

Traceback (most recent call last):
  File "/usr/local/lib/python3.6/dist-packages/flask/app.py", line 1982, in wsgi_app
    response = self.full_dispatch_request()
  File "/usr/local/lib/python3.6/dist-packages/flask/app.py", line 1614, in full_dispatch_request
    rv = self.handle_user_exception(e)
  File "/usr/local/lib/python3.6/dist-packages/flask/app.py", line 1517, in handle_user_exception
    reraise(exc_type, exc_value, tb)
  File "/usr/local/lib/python3.6/dist-packages/flask/_compat.py", line 33, in reraise
    raise value
  File "/usr/local/lib/python3.6/dist-packages/flask/app.py", line 1612, in full_dispatch_request
    rv = self.dispatch_request()
  File "/usr/local/lib/python3.6/dist-packages/flask/app.py", line 1598, in dispatch_request
    return self.view_functions[rule.endpoint](**req.view_args)
  File "/home/ubuntu/SIH-2020/app/routes.py", line 528, in get_po_invoice
    logger.error(str(e) + "on line no: " + exc_tb.tb_lineno)
NameError: name 'logger' is not defined
[2020-07-31 13:30:33,537] [INFO]: <Request 'http://3.215.183.155/api/services/v1/get_po_invoice' [POST]> [in /home/ubuntu/SIH-2020/app/routes.py:505]
[2020-07-31 13:30:33,538] [INFO]: reached po invoice 1 [in /home/ubuntu/SIH-2020/app/routes.py:511]
[2020-07-31 13:30:33,545] [INFO]: po_5f157208ea95723b48ff59f7.pdf [in /home/ubuntu/SIH-2020/app/routes.py:517]
[2020-07-31 13:30:33,618] [INFO]: http://3.215.183.155/static/po/po_5f157208ea95723b48ff59f7.pdf [in /home/ubuntu/SIH-2020/app/routes.py:523]
[2020-07-31 13:30:45,546] [INFO]: <Request 'http://3.215.183.155/api/services/v1/get_po_invoice' [POST]> [in /home/ubuntu/SIH-2020/app/routes.py:505]
[2020-07-31 13:30:45,546] [INFO]: reached po invoice 1 [in /home/ubuntu/SIH-2020/app/routes.py:511]
[2020-07-31 13:30:45,554] [INFO]: po_5f10af728bdd08981754b329.pdf [in /home/ubuntu/SIH-2020/app/routes.py:517]
[2020-07-31 13:30:45,629] [INFO]: http://3.215.183.155/static/po/po_5f10af728bdd08981754b329.pdf [in /home/ubuntu/SIH-2020/app/routes.py:523]
[2020-07-31 13:30:47,515] [INFO]: <Request 'http://3.215.183.155/api/services/v1/get_po_invoice' [POST]> [in /home/ubuntu/SIH-2020/app/routes.py:505]
[2020-07-31 13:30:47,516] [INFO]: reached po invoice 1 [in /home/ubuntu/SIH-2020/app/routes.py:511]
[2020-07-31 13:30:47,520] [ERROR]: Exception on /api/services/v1/get_po_invoice [POST] [in /usr/local/lib/python3.6/dist-packages/flask/app.py:1560]
Traceback (most recent call last):
  File "/home/ubuntu/SIH-2020/app/routes.py", line 514, in get_po_invoice
    content = db.po.find_one({'_id':ObjectId(data['Data']['po_id'])})
KeyError: 'po_id'

During handling of the above exception, another exception occurred:

Traceback (most recent call last):
  File "/usr/local/lib/python3.6/dist-packages/flask/app.py", line 1982, in wsgi_app
    response = self.full_dispatch_request()
  File "/usr/local/lib/python3.6/dist-packages/flask/app.py", line 1614, in full_dispatch_request
    rv = self.handle_user_exception(e)
  File "/usr/local/lib/python3.6/dist-packages/flask/app.py", line 1517, in handle_user_exception
    reraise(exc_type, exc_value, tb)
  File "/usr/local/lib/python3.6/dist-packages/flask/_compat.py", line 33, in reraise
    raise value
  File "/usr/local/lib/python3.6/dist-packages/flask/app.py", line 1612, in full_dispatch_request
    rv = self.dispatch_request()
  File "/usr/local/lib/python3.6/dist-packages/flask/app.py", line 1598, in dispatch_request
    return self.view_functions[rule.endpoint](**req.view_args)
  File "/home/ubuntu/SIH-2020/app/routes.py", line 528, in get_po_invoice
    logger.error(str(e) + "on line no: " + exc_tb.tb_lineno)
NameError: name 'logger' is not defined
[2020-07-31 13:31:06,203] [INFO]: <Request 'http://3.215.183.155/api/services/v1/get_po_invoice' [POST]> [in /home/ubuntu/SIH-2020/app/routes.py:505]
[2020-07-31 13:31:06,204] [INFO]: reached po invoice 1 [in /home/ubuntu/SIH-2020/app/routes.py:511]
[2020-07-31 13:31:06,211] [INFO]: po_5f217656dc1245d38023b9e6.pdf [in /home/ubuntu/SIH-2020/app/routes.py:517]
[2020-07-31 13:31:06,286] [INFO]: http://3.215.183.155/static/po/po_5f217656dc1245d38023b9e6.pdf [in /home/ubuntu/SIH-2020/app/routes.py:523]
[2020-07-31 13:31:15,070] [INFO]: <Request 'http://3.215.183.155/api/services/v1/get_po_invoice' [POST]> [in /home/ubuntu/SIH-2020/app/routes.py:505]
[2020-07-31 13:31:15,070] [INFO]: reached po invoice 1 [in /home/ubuntu/SIH-2020/app/routes.py:511]
