[2020-08-01 08:17:01,294] [INFO]: po_5f24457826c0d4641cd2dd35.pdf [in /home/ubuntu/SIH-2020/app/routes.py:515]
[2020-08-01 08:17:01,378] [INFO]: http://3.92.96.170/static/po/po_5f24457826c0d4641cd2dd35.pdf [in /home/ubuntu/SIH-2020/app/routes.py:521]
[2020-08-01 08:17:04,010] [INFO]: <Request 'http://3.92.96.170/api/services/v1/get_po_invoice' [POST]> [in /home/ubuntu/SIH-2020/app/routes.py:503]
[2020-08-01 08:17:04,010] [INFO]: reached po invoice 1 [in /home/ubuntu/SIH-2020/app/routes.py:509]
[2020-08-01 08:17:04,015] [ERROR]: Exception on /api/services/v1/get_po_invoice [POST] [in /home/ubuntu/.local/lib/python3.6/site-packages/flask/app.py:1761]
Traceback (most recent call last):
  File "/home/ubuntu/SIH-2020/app/routes.py", line 512, in get_po_invoice
    content = db.po.find_one({'_id':ObjectId(data['Data']['po_id'])})
KeyError: 'po_id'

During handling of the above exception, another exception occurred:

Traceback (most recent call last):
  File "/home/ubuntu/.local/lib/python3.6/site-packages/flask/app.py", line 2292, in wsgi_app
    response = self.full_dispatch_request()
  File "/home/ubuntu/.local/lib/python3.6/site-packages/flask/app.py", line 1815, in full_dispatch_request
    rv = self.handle_user_exception(e)
  File "/home/ubuntu/.local/lib/python3.6/site-packages/flask/app.py", line 1718, in handle_user_exception
    reraise(exc_type, exc_value, tb)
  File "/home/ubuntu/.local/lib/python3.6/site-packages/flask/_compat.py", line 35, in reraise
    raise value
  File "/home/ubuntu/.local/lib/python3.6/site-packages/flask/app.py", line 1813, in full_dispatch_request
    rv = self.dispatch_request()
  File "/home/ubuntu/.local/lib/python3.6/site-packages/flask/app.py", line 1799, in dispatch_request
    return self.view_functions[rule.endpoint](**req.view_args)
  File "/home/ubuntu/SIH-2020/app/routes.py", line 526, in get_po_invoice
    logger.error(str(e) + "on line no: " + exc_tb.tb_lineno)
NameError: name 'logger' is not defined
[2020-08-01 08:17:09,127] [INFO]: <Request 'http://3.92.96.170/api/services/v1/get_po_invoice' [POST]> [in /home/ubuntu/SIH-2020/app/routes.py:503]
[2020-08-01 08:17:09,127] [INFO]: reached po invoice 1 [in /home/ubuntu/SIH-2020/app/routes.py:509]
[2020-08-01 08:17:09,135] [INFO]: po_5f24457826c0d4641cd2dd35.pdf [in /home/ubuntu/SIH-2020/app/routes.py:515]
[2020-08-01 08:17:09,211] [INFO]: http://3.92.96.170/static/po/po_5f24457826c0d4641cd2dd35.pdf [in /home/ubuntu/SIH-2020/app/routes.py:521]
[2020-08-01 08:20:40,735] [INFO]: <Request 'http://3.92.96.170/api/services/v1/get_po_invoice' [POST]> [in /home/ubuntu/SIH-2020/app/routes.py:503]
[2020-08-01 08:20:40,736] [INFO]: reached po invoice 1 [in /home/ubuntu/SIH-2020/app/routes.py:509]
[2020-08-01 08:20:40,744] [INFO]: po_5f114408e257dd728e757d66.pdf [in /home/ubuntu/SIH-2020/app/routes.py:515]
[2020-08-01 08:20:40,817] [INFO]: http://3.92.96.170/static/po/po_5f114408e257dd728e757d66.pdf [in /home/ubuntu/SIH-2020/app/routes.py:521]
[2020-08-01 08:20:43,372] [INFO]: <Request 'http://3.92.96.170/api/services/v1/get_po_invoice' [POST]> [in /home/ubuntu/SIH-2020/app/routes.py:503]
[2020-08-01 08:20:43,372] [INFO]: reached po invoice 1 [in /home/ubuntu/SIH-2020/app/routes.py:509]
[2020-08-01 08:20:43,380] [INFO]: po_5f114408e257dd728e757d66.pdf [in /home/ubuntu/SIH-2020/app/routes.py:515]
[2020-08-01 08:20:43,454] [INFO]: http://3.92.96.170/static/po/po_5f114408e257dd728e757d66.pdf [in /home/ubuntu/SIH-2020/app/routes.py:521]
[2020-08-01 08:20:51,632] [INFO]: <Request 'http://3.92.96.170/api/services/v1/get_po_invoice' [POST]> [in /home/ubuntu/SIH-2020/app/routes.py:503]
[2020-08-01 08:20:51,633] [INFO]: reached po invoice 1 [in /home/ubuntu/SIH-2020/app/routes.py:509]
[2020-08-01 08:20:51,638] [ERROR]: Exception on /api/services/v1/get_po_invoice [POST] [in /home/ubuntu/.local/lib/python3.6/site-packages/flask/app.py:1761]
Traceback (most recent call last):
  File "/home/ubuntu/SIH-2020/app/routes.py", line 512, in get_po_invoice
    content = db.po.find_one({'_id':ObjectId(data['Data']['po_id'])})
KeyError: 'po_id'

During handling of the above exception, another exception occurred:

Traceback (most recent call last):
  File "/home/ubuntu/.local/lib/python3.6/site-packages/flask/app.py", line 2292, in wsgi_app
    response = self.full_dispatch_request()
  File "/home/ubuntu/.local/lib/python3.6/site-packages/flask/app.py", line 1815, in full_dispatch_request
    rv = self.handle_user_exception(e)
  File "/home/ubuntu/.local/lib/python3.6/site-packages/flask/app.py", line 1718, in handle_user_exception
    reraise(exc_type, exc_value, tb)
  File "/home/ubuntu/.local/lib/python3.6/site-packages/flask/_compat.py", line 35, in reraise
    raise value
  File "/home/ubuntu/.local/lib/python3.6/site-packages/flask/app.py", line 1813, in full_dispatch_request
    rv = self.dispatch_request()
  File "/home/ubuntu/.local/lib/python3.6/site-packages/flask/app.py", line 1799, in dispatch_request
    return self.view_functions[rule.endpoint](**req.view_args)
  File "/home/ubuntu/SIH-2020/app/routes.py", line 526, in get_po_invoice
    logger.error(str(e) + "on line no: " + exc_tb.tb_lineno)
NameError: name 'logger' is not defined
[2020-08-01 08:22:35,187] [INFO]: <Request 'http://3.92.96.170/api/services/v1/get_po_invoice' [POST]> [in /home/ubuntu/SIH-2020/app/routes.py:503]
[2020-08-01 08:22:35,188] [INFO]: reached po invoice 1 [in /home/ubuntu/SIH-2020/app/routes.py:509]
[2020-08-01 08:22:35,192] [ERROR]: Exception on /api/services/v1/get_po_invoice [POST] [in /home/ubuntu/.local/lib/python3.6/site-packages/flask/app.py:1761]
Traceback (most recent call last):
  File "/home/ubuntu/SIH-2020/app/routes.py", line 512, in get_po_invoice
    content = db.po.find_one({'_id':ObjectId(data['Data']['po_id'])})
KeyError: 'po_id'

During handling of the above exception, another exception occurred:

Traceback (most recent call last):
  File "/home/ubuntu/.local/lib/python3.6/site-packages/flask/app.py", line 2292, in wsgi_app
    response = self.full_dispatch_request()
  File "/home/ubuntu/.local/lib/python3.6/site-packages/flask/app.py", line 1815, in full_dispatch_request
    rv = self.handle_user_exception(e)
  File "/home/ubuntu/.local/lib/python3.6/site-packages/flask/app.py", line 1718, in handle_user_exception
    reraise(exc_type, exc_value, tb)
  File "/home/ubuntu/.local/lib/python3.6/site-packages/flask/_compat.py", line 35, in reraise
    raise value
  File "/home/ubuntu/.local/lib/python3.6/site-packages/flask/app.py", line 1813, in full_dispatch_request
    rv = self.dispatch_request()
  File "/home/ubuntu/.local/lib/python3.6/site-packages/flask/app.py", line 1799, in dispatch_request
    return self.view_functions[rule.endpoint](**req.view_args)
  File "/home/ubuntu/SIH-2020/app/routes.py", line 526, in get_po_invoice
    logger.error(str(e) + "on line no: " + exc_tb.tb_lineno)
NameError: name 'logger' is not defined
[2020-08-01 15:40:32,412] [INFO]: Inside get asset api [in /home/ubuntu/SIH-2020/app/routes.py:928]
[2020-08-01 15:40:32,412] [INFO]: {'Data': {'username': 'preyash_seller'}} [in /home/ubuntu/SIH-2020/app/routes.py:931]
[2020-08-01 16:47:19,446] [INFO]: {'provider': 'username', 'Data': {'serial_no': ' bis1'}} [in /home/ubuntu/SIH-2020/app/routes.py:993]
[2020-08-01 16:48:06,337] [INFO]: {'provider': 'username', 'Data': {'serial_no': 'PUCT8DkJNpU8vxgkALJGqd'}} [in /home/ubuntu/SIH-2020/app/routes.py:993]
[2020-08-01 16:48:09,627] [INFO]: {'provider': 'username', 'Data': {'serial_no': 'bis1'}} [in /home/ubuntu/SIH-2020/app/routes.py:993]
[2020-08-01 16:53:55,897] [INFO]: <Request 'http://3.92.96.170/api/services/v1/get_po_invoice' [POST]> [in /home/ubuntu/SIH-2020/app/routes.py:503]
[2020-08-01 16:53:55,898] [INFO]: reached po invoice 1 [in /home/ubuntu/SIH-2020/app/routes.py:509]
[2020-08-01 16:53:55,902] [ERROR]: Exception on /api/services/v1/get_po_invoice [POST] [in /home/ubuntu/.local/lib/python3.6/site-packages/flask/app.py:1761]
Traceback (most recent call last):
  File "/home/ubuntu/SIH-2020/app/routes.py", line 512, in get_po_invoice
    content = db.po.find_one({'_id':ObjectId(data['Data']['po_id'])})
KeyError: 'po_id'

During handling of the above exception, another exception occurred:

Traceback (most recent call last):
  File "/home/ubuntu/.local/lib/python3.6/site-packages/flask/app.py", line 2292, in wsgi_app
    response = self.full_dispatch_request()
  File "/home/ubuntu/.local/lib/python3.6/site-packages/flask/app.py", line 1815, in full_dispatch_request
    rv = self.handle_user_exception(e)
  File "/home/ubuntu/.local/lib/python3.6/site-packages/flask/app.py", line 1718, in handle_user_exception
    reraise(exc_type, exc_value, tb)
  File "/home/ubuntu/.local/lib/python3.6/site-packages/flask/_compat.py", line 35, in reraise
    raise value
  File "/home/ubuntu/.local/lib/python3.6/site-packages/flask/app.py", line 1813, in full_dispatch_request
    rv = self.dispatch_request()
  File "/home/ubuntu/.local/lib/python3.6/site-packages/flask/app.py", line 1799, in dispatch_request
    return self.view_functions[rule.endpoint](**req.view_args)
  File "/home/ubuntu/SIH-2020/app/routes.py", line 526, in get_po_invoice
    logger.error(str(e) + "on line no: " + exc_tb.tb_lineno)
NameError: name 'logger' is not defined
[2020-08-01 16:56:13,867] [INFO]: Inside get asset api [in /home/ubuntu/SIH-2020/app/routes.py:928]
[2020-08-01 16:56:13,867] [INFO]: {'provider': 'username', 'Data': {'username': 'ghosh_recycler'}} [in /home/ubuntu/SIH-2020/app/routes.py:931]
[2020-08-01 17:43:03,103] [INFO]: Inside get asset api [in /home/ubuntu/SIH-2020/app/routes.py:928]
[2020-08-01 17:43:03,104] [INFO]: {'Data': {'username': 'preyash_seller'}} [in /home/ubuntu/SIH-2020/app/routes.py:931]
[2020-08-01 18:00:50,819] [INFO]: {'provider': 'username', 'Data': {'serial_no': 'PUCT8DkJNpU8vxgkALJGqd'}} [in /home/ubuntu/SIH-2020/app/routes.py:993]
[2020-08-01 18:00:55,441] [INFO]: {'provider': 'username', 'Data': {'serial_no': '2o76GcYaPSwMXFJd6wQsJX'}} [in /home/ubuntu/SIH-2020/app/routes.py:993]
[2020-08-01 18:02:10,616] [INFO]: {'provider': 'username', 'Data': {'serial_no': ' '}} [in /home/ubuntu/SIH-2020/app/routes.py:993]
