[2020-07-10 13:44:09,041] [ERROR]: Exception on /index [GET] [in /home/ubuntu/.local/lib/python3.6/site-packages/flask/app.py:1560]
Traceback (most recent call last):
  File "/home/ubuntu/.local/lib/python3.6/site-packages/flask/app.py", line 1982, in wsgi_app
    response = self.full_dispatch_request()
  File "/home/ubuntu/.local/lib/python3.6/site-packages/flask/app.py", line 1614, in full_dispatch_request
    rv = self.handle_user_exception(e)
  File "/home/ubuntu/.local/lib/python3.6/site-packages/flask/app.py", line 1517, in handle_user_exception
    reraise(exc_type, exc_value, tb)
  File "/home/ubuntu/.local/lib/python3.6/site-packages/flask/_compat.py", line 33, in reraise
    raise value
  File "/home/ubuntu/.local/lib/python3.6/site-packages/flask/app.py", line 1612, in full_dispatch_request
    rv = self.dispatch_request()
  File "/home/ubuntu/.local/lib/python3.6/site-packages/flask/app.py", line 1598, in dispatch_request
    return self.view_functions[rule.endpoint](**req.view_args)
  File "/home/ubuntu/.local/lib/python3.6/site-packages/flask_login/utils.py", line 272, in decorated_view
    return func(*args, **kwargs)
  File "/home/ubuntu/SIH-2020/app/routes.py", line 194, in index
    s = s +", " + i
TypeError: must be str, not list
