[2020-06-27 10:21:05,039] [INFO]: Supply Chain Startup [in /home/ubuntu/SIH-2020/app/__init__.py:50]
[2020-06-27 10:21:34,173] [INFO]: Supply Chain Startup [in /home/ubuntu/SIH-2020/app/__init__.py:50]
[2020-06-27 10:22:01,180] [INFO]: Supply Chain Startup [in /home/ubuntu/SIH-2020/app/__init__.py:50]
[2020-06-27 10:22:01,249] [INFO]: Supply Chain Startup [in /home/ubuntu/SIH-2020/app/__init__.py:50]
[2020-06-27 10:22:01,346] [INFO]: Supply Chain Startup [in /home/ubuntu/SIH-2020/app/__init__.py:50]
[2020-06-27 10:23:57,614] [ERROR]: Exception on /index [GET] [in /home/ubuntu/.local/lib/python3.6/site-packages/flask/app.py:1560]
Traceback (most recent call last):
  File "/home/ubuntu/.local/lib/python3.6/site-packages/flask/app.py", line 1982, in wsgi_app
    response = self.full_dispatch_request()
  File "/home/ubuntu/.local/lib/python3.6/site-packages/flask/app.py", line 1614, in full_dispatch_request
    rv = self.handle_user_exception(e)
  File "/home/ubuntu/.local/lib/python3.6/site-packages/flask/app.py", line 1517, in handle_user_exception
    reraise(exc_type, exc_value, tb)
  File "/home/ubuntu/.local/lib/python3.6/site-packages/flask/_compat.py", line 33, in reraise
    raise value
  File "/home/ubuntu/.local/lib/python3.6/site-packages/flask/app.py", line 1612, in full_dispatch_request
    rv = self.dispatch_request()
  File "/home/ubuntu/.local/lib/python3.6/site-packages/flask/app.py", line 1598, in dispatch_request
    return self.view_functions[rule.endpoint](**req.view_args)
  File "/home/ubuntu/.local/lib/python3.6/site-packages/flask_login/utils.py", line 272, in decorated_view
    return func(*args, **kwargs)
  File "/home/ubuntu/SIH-2020/app/routes.py", line 189, in index
    flash('Pub: '+fin['public_key'])
TypeError: 'NoneType' object is not subscriptable
[2020-06-27 10:24:01,556] [ERROR]: Exception on /index [GET] [in /home/ubuntu/.local/lib/python3.6/site-packages/flask/app.py:1560]
Traceback (most recent call last):
  File "/home/ubuntu/.local/lib/python3.6/site-packages/flask/app.py", line 1982, in wsgi_app
    response = self.full_dispatch_request()
  File "/home/ubuntu/.local/lib/python3.6/site-packages/flask/app.py", line 1614, in full_dispatch_request
    rv = self.handle_user_exception(e)
  File "/home/ubuntu/.local/lib/python3.6/site-packages/flask/app.py", line 1517, in handle_user_exception
    reraise(exc_type, exc_value, tb)
  File "/home/ubuntu/.local/lib/python3.6/site-packages/flask/_compat.py", line 33, in reraise
    raise value
  File "/home/ubuntu/.local/lib/python3.6/site-packages/flask/app.py", line 1612, in full_dispatch_request
    rv = self.dispatch_request()
  File "/home/ubuntu/.local/lib/python3.6/site-packages/flask/app.py", line 1598, in dispatch_request
    return self.view_functions[rule.endpoint](**req.view_args)
  File "/home/ubuntu/.local/lib/python3.6/site-packages/flask_login/utils.py", line 272, in decorated_view
    return func(*args, **kwargs)
  File "/home/ubuntu/SIH-2020/app/routes.py", line 189, in index
    flash('Pub: '+fin['public_key'])
TypeError: 'NoneType' object is not subscriptable
[2020-06-27 10:24:03,155] [ERROR]: Exception on /transaction [GET] [in /home/ubuntu/.local/lib/python3.6/site-packages/flask/app.py:1560]
Traceback (most recent call last):
  File "/home/ubuntu/.local/lib/python3.6/site-packages/flask/app.py", line 1982, in wsgi_app
    response = self.full_dispatch_request()
  File "/home/ubuntu/.local/lib/python3.6/site-packages/flask/app.py", line 1614, in full_dispatch_request
    rv = self.handle_user_exception(e)
  File "/home/ubuntu/.local/lib/python3.6/site-packages/flask/app.py", line 1517, in handle_user_exception
    reraise(exc_type, exc_value, tb)
  File "/home/ubuntu/.local/lib/python3.6/site-packages/flask/_compat.py", line 33, in reraise
    raise value
  File "/home/ubuntu/.local/lib/python3.6/site-packages/flask/app.py", line 1612, in full_dispatch_request
    rv = self.dispatch_request()
  File "/home/ubuntu/.local/lib/python3.6/site-packages/flask/app.py", line 1598, in dispatch_request
    return self.view_functions[rule.endpoint](**req.view_args)
  File "/home/ubuntu/.local/lib/python3.6/site-packages/flask_login/utils.py", line 272, in decorated_view
    return func(*args, **kwargs)
  File "/home/ubuntu/SIH-2020/app/routes.py", line 295, in transaction
    role = fin['Role']
TypeError: 'NoneType' object is not subscriptable
[2020-06-27 10:24:04,571] [ERROR]: Exception on /index [GET] [in /home/ubuntu/.local/lib/python3.6/site-packages/flask/app.py:1560]
Traceback (most recent call last):
  File "/home/ubuntu/.local/lib/python3.6/site-packages/flask/app.py", line 1982, in wsgi_app
    response = self.full_dispatch_request()
  File "/home/ubuntu/.local/lib/python3.6/site-packages/flask/app.py", line 1614, in full_dispatch_request
    rv = self.handle_user_exception(e)
  File "/home/ubuntu/.local/lib/python3.6/site-packages/flask/app.py", line 1517, in handle_user_exception
    reraise(exc_type, exc_value, tb)
  File "/home/ubuntu/.local/lib/python3.6/site-packages/flask/_compat.py", line 33, in reraise
    raise value
  File "/home/ubuntu/.local/lib/python3.6/site-packages/flask/app.py", line 1612, in full_dispatch_request
    rv = self.dispatch_request()
  File "/home/ubuntu/.local/lib/python3.6/site-packages/flask/app.py", line 1598, in dispatch_request
    return self.view_functions[rule.endpoint](**req.view_args)
  File "/home/ubuntu/.local/lib/python3.6/site-packages/flask_login/utils.py", line 272, in decorated_view
    return func(*args, **kwargs)
  File "/home/ubuntu/SIH-2020/app/routes.py", line 189, in index
    flash('Pub: '+fin['public_key'])
TypeError: 'NoneType' object is not subscriptable
[2020-06-27 10:24:41,027] [ERROR]: Exception on /index [GET] [in /home/ubuntu/.local/lib/python3.6/site-packages/flask/app.py:1560]
Traceback (most recent call last):
  File "/home/ubuntu/.local/lib/python3.6/site-packages/flask/app.py", line 1982, in wsgi_app
    response = self.full_dispatch_request()
  File "/home/ubuntu/.local/lib/python3.6/site-packages/flask/app.py", line 1614, in full_dispatch_request
    rv = self.handle_user_exception(e)
  File "/home/ubuntu/.local/lib/python3.6/site-packages/flask/app.py", line 1517, in handle_user_exception
    reraise(exc_type, exc_value, tb)
  File "/home/ubuntu/.local/lib/python3.6/site-packages/flask/_compat.py", line 33, in reraise
    raise value
  File "/home/ubuntu/.local/lib/python3.6/site-packages/flask/app.py", line 1612, in full_dispatch_request
    rv = self.dispatch_request()
  File "/home/ubuntu/.local/lib/python3.6/site-packages/flask/app.py", line 1598, in dispatch_request
    return self.view_functions[rule.endpoint](**req.view_args)
  File "/home/ubuntu/.local/lib/python3.6/site-packages/flask_login/utils.py", line 272, in decorated_view
    return func(*args, **kwargs)
  File "/home/ubuntu/SIH-2020/app/routes.py", line 189, in index
    flash('Pub: '+fin['public_key'])
TypeError: 'NoneType' object is not subscriptable
[2020-06-27 10:26:25,333] [INFO]: Supply Chain Startup [in /home/ubuntu/SIH-2020/app/__init__.py:50]
[2020-06-27 10:26:25,342] [INFO]: Supply Chain Startup [in /home/ubuntu/SIH-2020/app/__init__.py:50]
[2020-06-27 10:26:25,462] [INFO]: Supply Chain Startup [in /home/ubuntu/SIH-2020/app/__init__.py:50]
[2020-07-05 02:49:54,558] [ERROR]: Exception on /search [GET] [in /home/ubuntu/.local/lib/python3.6/site-packages/flask/app.py:1560]
Traceback (most recent call last):
  File "/home/ubuntu/.local/lib/python3.6/site-packages/flask/app.py", line 1982, in wsgi_app
    response = self.full_dispatch_request()
  File "/home/ubuntu/.local/lib/python3.6/site-packages/flask/app.py", line 1614, in full_dispatch_request
    rv = self.handle_user_exception(e)
  File "/home/ubuntu/.local/lib/python3.6/site-packages/flask/app.py", line 1517, in handle_user_exception
    reraise(exc_type, exc_value, tb)
  File "/home/ubuntu/.local/lib/python3.6/site-packages/flask/_compat.py", line 33, in reraise
    raise value
  File "/home/ubuntu/.local/lib/python3.6/site-packages/flask/app.py", line 1612, in full_dispatch_request
    rv = self.dispatch_request()
  File "/home/ubuntu/.local/lib/python3.6/site-packages/flask/app.py", line 1598, in dispatch_request
    return self.view_functions[rule.endpoint](**req.view_args)
  File "/home/ubuntu/SIH-2020/app/routes.py", line 303, in search
    fin = mongo.db.users.find_one({ 'username':session['username'] })
  File "/home/ubuntu/.local/lib/python3.6/site-packages/werkzeug/local.py", line 378, in <lambda>
    __getitem__ = lambda x, i: x._get_current_object()[i]
KeyError: 'username'
[2020-07-07 16:26:37,580] [INFO]: Supply Chain Startup [in /home/ubuntu/SIH-2020/app/__init__.py:50]
[2020-07-07 16:26:37,703] [INFO]: Supply Chain Startup [in /home/ubuntu/SIH-2020/app/__init__.py:50]
[2020-07-07 16:26:37,732] [INFO]: Supply Chain Startup [in /home/ubuntu/SIH-2020/app/__init__.py:50]
[2020-07-07 16:44:33,936] [INFO]: Supply Chain Startup [in /home/ubuntu/SIH-2020/app/__init__.py:50]
[2020-07-07 16:44:33,970] [INFO]: Supply Chain Startup [in /home/ubuntu/SIH-2020/app/__init__.py:50]
[2020-07-07 16:44:33,990] [INFO]: Supply Chain Startup [in /home/ubuntu/SIH-2020/app/__init__.py:50]
