[2020-07-07 17:03:56,241] [ERROR]: Exception on /sales [POST] [in /home/ubuntu/.local/lib/python3.6/site-packages/flask/app.py:1560]
Traceback (most recent call last):
  File "/home/ubuntu/.local/lib/python3.6/site-packages/flask/app.py", line 1982, in wsgi_app
    response = self.full_dispatch_request()
  File "/home/ubuntu/.local/lib/python3.6/site-packages/flask/app.py", line 1614, in full_dispatch_request
    rv = self.handle_user_exception(e)
  File "/home/ubuntu/.local/lib/python3.6/site-packages/flask/app.py", line 1517, in handle_user_exception
    reraise(exc_type, exc_value, tb)
  File "/home/ubuntu/.local/lib/python3.6/site-packages/flask/_compat.py", line 33, in reraise
    raise value
  File "/home/ubuntu/.local/lib/python3.6/site-packages/flask/app.py", line 1612, in full_dispatch_request
    rv = self.dispatch_request()
  File "/home/ubuntu/.local/lib/python3.6/site-packages/flask/app.py", line 1598, in dispatch_request
    return self.view_functions[rule.endpoint](**req.view_args)
  File "/home/ubuntu/.local/lib/python3.6/site-packages/flask_login/utils.py", line 272, in decorated_view
    return func(*args, **kwargs)
  File "/home/ubuntu/SIH-2020/app/routes.py", line 355, in sales
    own = mongo.db.users.find({ 'username': usern })
NameError: name 'usern' is not defined
[2020-07-07 17:05:14,907] [INFO]: Supply Chain Startup [in /home/ubuntu/SIH-2020/app/__init__.py:50]
[2020-07-07 17:05:14,927] [INFO]: Supply Chain Startup [in /home/ubuntu/SIH-2020/app/__init__.py:50]
[2020-07-07 17:05:14,958] [INFO]: Supply Chain Startup [in /home/ubuntu/SIH-2020/app/__init__.py:50]
[2020-07-07 17:05:21,791] [ERROR]: Exception on /sales [POST] [in /home/ubuntu/.local/lib/python3.6/site-packages/flask/app.py:1560]
Traceback (most recent call last):
  File "/home/ubuntu/.local/lib/python3.6/site-packages/flask/app.py", line 1982, in wsgi_app
    response = self.full_dispatch_request()
  File "/home/ubuntu/.local/lib/python3.6/site-packages/flask/app.py", line 1614, in full_dispatch_request
    rv = self.handle_user_exception(e)
  File "/home/ubuntu/.local/lib/python3.6/site-packages/flask/app.py", line 1517, in handle_user_exception
    reraise(exc_type, exc_value, tb)
  File "/home/ubuntu/.local/lib/python3.6/site-packages/flask/_compat.py", line 33, in reraise
    raise value
  File "/home/ubuntu/.local/lib/python3.6/site-packages/flask/app.py", line 1612, in full_dispatch_request
    rv = self.dispatch_request()
  File "/home/ubuntu/.local/lib/python3.6/site-packages/flask/app.py", line 1598, in dispatch_request
    return self.view_functions[rule.endpoint](**req.view_args)
  File "/home/ubuntu/.local/lib/python3.6/site-packages/flask_login/utils.py", line 272, in decorated_view
    return func(*args, **kwargs)
  File "/home/ubuntu/SIH-2020/app/routes.py", line 358, in sales
    owned = len(own['owned'])
  File "/usr/local/lib/python3.6/dist-packages/pymongo/cursor.py", line 618, in __getitem__
    "instances" % index)
TypeError: index 'owned' cannot be applied to Cursor instances
[2020-07-07 17:08:26,406] [INFO]: Supply Chain Startup [in /home/ubuntu/SIH-2020/app/__init__.py:50]
[2020-07-07 17:08:26,437] [INFO]: Supply Chain Startup [in /home/ubuntu/SIH-2020/app/__init__.py:50]
[2020-07-07 17:08:26,579] [INFO]: Supply Chain Startup [in /home/ubuntu/SIH-2020/app/__init__.py:50]
[2020-07-07 17:08:40,540] [ERROR]: Exception on /sales [POST] [in /home/ubuntu/.local/lib/python3.6/site-packages/flask/app.py:1560]
Traceback (most recent call last):
  File "/home/ubuntu/.local/lib/python3.6/site-packages/flask/app.py", line 1982, in wsgi_app
    response = self.full_dispatch_request()
  File "/home/ubuntu/.local/lib/python3.6/site-packages/flask/app.py", line 1614, in full_dispatch_request
    rv = self.handle_user_exception(e)
  File "/home/ubuntu/.local/lib/python3.6/site-packages/flask/app.py", line 1517, in handle_user_exception
    reraise(exc_type, exc_value, tb)
  File "/home/ubuntu/.local/lib/python3.6/site-packages/flask/_compat.py", line 33, in reraise
    raise value
  File "/home/ubuntu/.local/lib/python3.6/site-packages/flask/app.py", line 1612, in full_dispatch_request
    rv = self.dispatch_request()
  File "/home/ubuntu/.local/lib/python3.6/site-packages/flask/app.py", line 1598, in dispatch_request
    return self.view_functions[rule.endpoint](**req.view_args)
  File "/home/ubuntu/.local/lib/python3.6/site-packages/flask_login/utils.py", line 272, in decorated_view
    return func(*args, **kwargs)
  File "/home/ubuntu/SIH-2020/app/routes.py", line 358, in sales
    owned = own['owned'].len()
  File "/usr/local/lib/python3.6/dist-packages/pymongo/cursor.py", line 618, in __getitem__
    "instances" % index)
TypeError: index 'owned' cannot be applied to Cursor instances
[2020-07-07 18:16:21,185] [ERROR]: Exception on /sales [POST] [in /home/ubuntu/.local/lib/python3.6/site-packages/flask/app.py:1560]
Traceback (most recent call last):
  File "/home/ubuntu/.local/lib/python3.6/site-packages/flask/app.py", line 1982, in wsgi_app
    response = self.full_dispatch_request()
  File "/home/ubuntu/.local/lib/python3.6/site-packages/flask/app.py", line 1614, in full_dispatch_request
    rv = self.handle_user_exception(e)
  File "/home/ubuntu/.local/lib/python3.6/site-packages/flask/app.py", line 1517, in handle_user_exception
    reraise(exc_type, exc_value, tb)
  File "/home/ubuntu/.local/lib/python3.6/site-packages/flask/_compat.py", line 33, in reraise
    raise value
  File "/home/ubuntu/.local/lib/python3.6/site-packages/flask/app.py", line 1612, in full_dispatch_request
    rv = self.dispatch_request()
  File "/home/ubuntu/.local/lib/python3.6/site-packages/flask/app.py", line 1598, in dispatch_request
    return self.view_functions[rule.endpoint](**req.view_args)
  File "/home/ubuntu/.local/lib/python3.6/site-packages/flask_login/utils.py", line 272, in decorated_view
    return func(*args, **kwargs)
  File "/home/ubuntu/SIH-2020/app/routes.py", line 358, in sales
    owned = own['owned'].len()
  File "/usr/local/lib/python3.6/dist-packages/pymongo/cursor.py", line 618, in __getitem__
    "instances" % index)
TypeError: index 'owned' cannot be applied to Cursor instances
[2020-07-07 18:19:48,950] [INFO]: Supply Chain Startup [in /home/ubuntu/SIH-2020/app/__init__.py:50]
[2020-07-07 18:19:49,019] [INFO]: Supply Chain Startup [in /home/ubuntu/SIH-2020/app/__init__.py:50]
[2020-07-07 18:19:49,108] [INFO]: Supply Chain Startup [in /home/ubuntu/SIH-2020/app/__init__.py:50]
[2020-07-07 18:19:53,185] [ERROR]: Exception on /sales [POST] [in /home/ubuntu/.local/lib/python3.6/site-packages/flask/app.py:1560]
Traceback (most recent call last):
  File "/home/ubuntu/.local/lib/python3.6/site-packages/flask/app.py", line 1982, in wsgi_app
    response = self.full_dispatch_request()
  File "/home/ubuntu/.local/lib/python3.6/site-packages/flask/app.py", line 1614, in full_dispatch_request
    rv = self.handle_user_exception(e)
  File "/home/ubuntu/.local/lib/python3.6/site-packages/flask/app.py", line 1517, in handle_user_exception
    reraise(exc_type, exc_value, tb)
  File "/home/ubuntu/.local/lib/python3.6/site-packages/flask/_compat.py", line 33, in reraise
    raise value
  File "/home/ubuntu/.local/lib/python3.6/site-packages/flask/app.py", line 1612, in full_dispatch_request
    rv = self.dispatch_request()
  File "/home/ubuntu/.local/lib/python3.6/site-packages/flask/app.py", line 1598, in dispatch_request
    return self.view_functions[rule.endpoint](**req.view_args)
  File "/home/ubuntu/.local/lib/python3.6/site-packages/flask_login/utils.py", line 272, in decorated_view
    return func(*args, **kwargs)
  File "/home/ubuntu/SIH-2020/app/routes.py", line 358, in sales
    owned = own['owned'].len()
AttributeError: 'list' object has no attribute 'len'
[2020-07-07 18:21:59,244] [INFO]: Supply Chain Startup [in /home/ubuntu/SIH-2020/app/__init__.py:50]
[2020-07-07 18:21:59,316] [INFO]: Supply Chain Startup [in /home/ubuntu/SIH-2020/app/__init__.py:50]
[2020-07-07 18:21:59,426] [INFO]: Supply Chain Startup [in /home/ubuntu/SIH-2020/app/__init__.py:50]
[2020-07-07 18:22:20,253] [ERROR]: Exception on /sales [POST] [in /home/ubuntu/.local/lib/python3.6/site-packages/flask/app.py:1560]
Traceback (most recent call last):
  File "/home/ubuntu/.local/lib/python3.6/site-packages/flask/app.py", line 1982, in wsgi_app
    response = self.full_dispatch_request()
  File "/home/ubuntu/.local/lib/python3.6/site-packages/flask/app.py", line 1614, in full_dispatch_request
    rv = self.handle_user_exception(e)
  File "/home/ubuntu/.local/lib/python3.6/site-packages/flask/app.py", line 1517, in handle_user_exception
    reraise(exc_type, exc_value, tb)
  File "/home/ubuntu/.local/lib/python3.6/site-packages/flask/_compat.py", line 33, in reraise
    raise value
  File "/home/ubuntu/.local/lib/python3.6/site-packages/flask/app.py", line 1612, in full_dispatch_request
    rv = self.dispatch_request()
  File "/home/ubuntu/.local/lib/python3.6/site-packages/flask/app.py", line 1598, in dispatch_request
    return self.view_functions[rule.endpoint](**req.view_args)
  File "/home/ubuntu/.local/lib/python3.6/site-packages/flask_login/utils.py", line 272, in decorated_view
    return func(*args, **kwargs)
  File "/home/ubuntu/SIH-2020/app/routes.py", line 359, in sales
    quantity = int(amount['quantity'])
  File "/usr/local/lib/python3.6/dist-packages/pymongo/cursor.py", line 618, in __getitem__
    "instances" % index)
TypeError: index 'quantity' cannot be applied to Cursor instances
[2020-07-07 18:24:54,394] [INFO]: Supply Chain Startup [in /home/ubuntu/SIH-2020/app/__init__.py:50]
[2020-07-07 18:24:54,448] [INFO]: Supply Chain Startup [in /home/ubuntu/SIH-2020/app/__init__.py:50]
[2020-07-07 18:24:54,486] [INFO]: Supply Chain Startup [in /home/ubuntu/SIH-2020/app/__init__.py:50]
