[2020-07-20 10:32:21,340] [INFO]: <Queue jute-tasks> [in /home/ubuntu/SIH-2020/app/models.py:18]
[2020-07-20 10:32:21,342] [INFO]: RQ JOB [in /home/ubuntu/SIH-2020/app/models.py:30]
[2020-07-20 10:32:21,342] [INFO]: <Job 66191645-f16d-4b59-9747-10a536bbbe2f: app.tasks.transfer_n_assets('preyash_seller', 'random', '5CM4mjdoqvWRKVWM8k4qYHbChgShCLZD6BneZTWaLrfZ', 1, ['J9k7PV7m3uGocLPSbdJdYv'])> [in /home/ubuntu/SIH-2020/app/models.py:31]
[2020-07-20 10:32:21,709] [INFO]: Supply Chain Startup [in ./app/__init__.py:54]
[2020-07-20 13:33:04,339] [INFO]: {'provider': 'username', 'Data': {'serial_no': 'bis1'}} [in /home/ubuntu/SIH-2020/app/routes.py:906]
[2020-07-20 13:33:37,794] [INFO]: {'provider': 'username', 'Data': {'serial_no': 'abc2'}} [in /home/ubuntu/SIH-2020/app/routes.py:906]
[2020-07-20 14:05:12,372] [INFO]: {'provider': 'username', 'Data': {'serial_no': 'bis1'}} [in /home/ubuntu/SIH-2020/app/routes.py:906]
[2020-07-20 15:18:09,467] [INFO]: {'provider': 'username', 'Data': {'serial_no': 'bis1'}} [in /home/ubuntu/SIH-2020/app/routes.py:906]
[2020-07-20 15:19:32,482] [INFO]: {'provider': 'username', 'Data': {'serial_no': 'bis1'}} [in /home/ubuntu/SIH-2020/app/routes.py:906]
[2020-07-20 15:19:37,331] [INFO]: {'provider': 'username', 'Data': {'serial_no': 'bis1'}} [in /home/ubuntu/SIH-2020/app/routes.py:906]
[2020-07-20 17:07:36,928] [INFO]: {'provider': 'username', 'Data': {'serial_no': 'J9k7PV7m3uGocLPSbdJdYv'}} [in /home/ubuntu/SIH-2020/app/routes.py:906]
[2020-07-20 17:20:51,937] [INFO]: {'provider': 'username', 'Data': {'serial_no': 'J9k7PV7m3uGocLPSbdJdYv'}} [in /home/ubuntu/SIH-2020/app/routes.py:906]
[2020-07-21 10:01:38,199] [ERROR]: Exception on /api/services/v1/order_finalize [POST] [in /home/ubuntu/.local/lib/python3.6/site-packages/flask/app.py:1560]
Traceback (most recent call last):
  File "/home/ubuntu/SIH-2020/app/routes.py", line 508, in order_finalize
    assets = assets['assets']
TypeError: 'NoneType' object is not subscriptable

During handling of the above exception, another exception occurred:

Traceback (most recent call last):
  File "/home/ubuntu/.local/lib/python3.6/site-packages/flask/app.py", line 1982, in wsgi_app
    the :attr:`before_first_request_funcs` and only exactly once per
  File "/home/ubuntu/.local/lib/python3.6/site-packages/flask/app.py", line 1614, in full_dispatch_request
    @setupmethod
  File "/home/ubuntu/.local/lib/python3.6/site-packages/flask/app.py", line 1517, in handle_user_exception
    self.add_template_global(f, name=name)
  File "/home/ubuntu/.local/lib/python3.6/site-packages/flask/_compat.py", line 33, in reraise
    from io import StringIO
  File "/home/ubuntu/.local/lib/python3.6/site-packages/flask/app.py", line 1612, in full_dispatch_request
    return f
  File "/home/ubuntu/.local/lib/python3.6/site-packages/flask/app.py", line 1598, in dispatch_request
  File "/home/ubuntu/SIH-2020/app/routes.py", line 534, in order_finalize
    logger.error(str(e) + "on line no: " + exc_tb.tb_lineno)
NameError: name 'logger' is not defined
[2020-07-21 10:01:40,223] [ERROR]: Exception on /api/services/v1/order_finalize [POST] [in /home/ubuntu/.local/lib/python3.6/site-packages/flask/app.py:1560]
Traceback (most recent call last):
  File "/home/ubuntu/SIH-2020/app/routes.py", line 508, in order_finalize
    assets = assets['assets']
TypeError: 'NoneType' object is not subscriptable

During handling of the above exception, another exception occurred:

Traceback (most recent call last):
  File "/home/ubuntu/.local/lib/python3.6/site-packages/flask/app.py", line 1982, in wsgi_app
    the :attr:`before_first_request_funcs` and only exactly once per
  File "/home/ubuntu/.local/lib/python3.6/site-packages/flask/app.py", line 1614, in full_dispatch_request
    @setupmethod
  File "/home/ubuntu/.local/lib/python3.6/site-packages/flask/app.py", line 1517, in handle_user_exception
    self.add_template_global(f, name=name)
  File "/home/ubuntu/.local/lib/python3.6/site-packages/flask/_compat.py", line 33, in reraise
    from io import StringIO
  File "/home/ubuntu/.local/lib/python3.6/site-packages/flask/app.py", line 1612, in full_dispatch_request
    return f
  File "/home/ubuntu/.local/lib/python3.6/site-packages/flask/app.py", line 1598, in dispatch_request
  File "/home/ubuntu/SIH-2020/app/routes.py", line 534, in order_finalize
    logger.error(str(e) + "on line no: " + exc_tb.tb_lineno)
NameError: name 'logger' is not defined
[2020-07-21 10:15:12,452] [ERROR]: Exception on /api/services/v1/order_finalize [POST] [in /home/ubuntu/.local/lib/python3.6/site-packages/flask/app.py:1560]
Traceback (most recent call last):
  File "/home/ubuntu/SIH-2020/app/routes.py", line 508, in order_finalize
    assets = assets['assets']
TypeError: 'NoneType' object is not subscriptable

During handling of the above exception, another exception occurred:

Traceback (most recent call last):
  File "/home/ubuntu/.local/lib/python3.6/site-packages/flask/app.py", line 1982, in wsgi_app
    the :attr:`before_first_request_funcs` and only exactly once per
  File "/home/ubuntu/.local/lib/python3.6/site-packages/flask/app.py", line 1614, in full_dispatch_request
    @setupmethod
  File "/home/ubuntu/.local/lib/python3.6/site-packages/flask/app.py", line 1517, in handle_user_exception
    self.add_template_global(f, name=name)
  File "/home/ubuntu/.local/lib/python3.6/site-packages/flask/_compat.py", line 33, in reraise
    from io import StringIO
  File "/home/ubuntu/.local/lib/python3.6/site-packages/flask/app.py", line 1612, in full_dispatch_request
    return f
  File "/home/ubuntu/.local/lib/python3.6/site-packages/flask/app.py", line 1598, in dispatch_request
  File "/home/ubuntu/SIH-2020/app/routes.py", line 534, in order_finalize
    logger.error(str(e) + "on line no: " + exc_tb.tb_lineno)
NameError: name 'logger' is not defined
[2020-07-21 10:15:13,008] [ERROR]: Exception on /api/services/v1/order_finalize [POST] [in /home/ubuntu/.local/lib/python3.6/site-packages/flask/app.py:1560]
Traceback (most recent call last):
  File "/home/ubuntu/SIH-2020/app/routes.py", line 508, in order_finalize
    assets = assets['assets']
TypeError: 'NoneType' object is not subscriptable

During handling of the above exception, another exception occurred:

Traceback (most recent call last):
  File "/home/ubuntu/.local/lib/python3.6/site-packages/flask/app.py", line 1982, in wsgi_app
    the :attr:`before_first_request_funcs` and only exactly once per
  File "/home/ubuntu/.local/lib/python3.6/site-packages/flask/app.py", line 1614, in full_dispatch_request
    @setupmethod
  File "/home/ubuntu/.local/lib/python3.6/site-packages/flask/app.py", line 1517, in handle_user_exception
    self.add_template_global(f, name=name)
  File "/home/ubuntu/.local/lib/python3.6/site-packages/flask/_compat.py", line 33, in reraise
    from io import StringIO
  File "/home/ubuntu/.local/lib/python3.6/site-packages/flask/app.py", line 1612, in full_dispatch_request
    return f
  File "/home/ubuntu/.local/lib/python3.6/site-packages/flask/app.py", line 1598, in dispatch_request
  File "/home/ubuntu/SIH-2020/app/routes.py", line 534, in order_finalize
    logger.error(str(e) + "on line no: " + exc_tb.tb_lineno)
NameError: name 'logger' is not defined
[2020-07-21 10:16:32,318] [ERROR]: Exception on /api/services/v1/order_finalize [POST] [in /home/ubuntu/.local/lib/python3.6/site-packages/flask/app.py:1560]
Traceback (most recent call last):
  File "/home/ubuntu/SIH-2020/app/routes.py", line 508, in order_finalize
    assets = assets['assets']
TypeError: 'NoneType' object is not subscriptable

During handling of the above exception, another exception occurred:

Traceback (most recent call last):
  File "/home/ubuntu/.local/lib/python3.6/site-packages/flask/app.py", line 1982, in wsgi_app
    the :attr:`before_first_request_funcs` and only exactly once per
  File "/home/ubuntu/.local/lib/python3.6/site-packages/flask/app.py", line 1614, in full_dispatch_request
    @setupmethod
  File "/home/ubuntu/.local/lib/python3.6/site-packages/flask/app.py", line 1517, in handle_user_exception
    self.add_template_global(f, name=name)
  File "/home/ubuntu/.local/lib/python3.6/site-packages/flask/_compat.py", line 33, in reraise
    from io import StringIO
  File "/home/ubuntu/.local/lib/python3.6/site-packages/flask/app.py", line 1612, in full_dispatch_request
    return f
  File "/home/ubuntu/.local/lib/python3.6/site-packages/flask/app.py", line 1598, in dispatch_request
  File "/home/ubuntu/SIH-2020/app/routes.py", line 534, in order_finalize
    logger.error(str(e) + "on line no: " + exc_tb.tb_lineno)
NameError: name 'logger' is not defined
[2020-07-21 10:16:34,573] [ERROR]: Exception on /api/services/v1/order_finalize [POST] [in /home/ubuntu/.local/lib/python3.6/site-packages/flask/app.py:1560]
Traceback (most recent call last):
  File "/home/ubuntu/SIH-2020/app/routes.py", line 508, in order_finalize
    assets = assets['assets']
TypeError: 'NoneType' object is not subscriptable

During handling of the above exception, another exception occurred:

Traceback (most recent call last):
  File "/home/ubuntu/.local/lib/python3.6/site-packages/flask/app.py", line 1982, in wsgi_app
    the :attr:`before_first_request_funcs` and only exactly once per
  File "/home/ubuntu/.local/lib/python3.6/site-packages/flask/app.py", line 1614, in full_dispatch_request
    @setupmethod
  File "/home/ubuntu/.local/lib/python3.6/site-packages/flask/app.py", line 1517, in handle_user_exception
    self.add_template_global(f, name=name)
  File "/home/ubuntu/.local/lib/python3.6/site-packages/flask/_compat.py", line 33, in reraise
    from io import StringIO
  File "/home/ubuntu/.local/lib/python3.6/site-packages/flask/app.py", line 1612, in full_dispatch_request
    return f
  File "/home/ubuntu/.local/lib/python3.6/site-packages/flask/app.py", line 1598, in dispatch_request
  File "/home/ubuntu/SIH-2020/app/routes.py", line 534, in order_finalize
    logger.error(str(e) + "on line no: " + exc_tb.tb_lineno)
NameError: name 'logger' is not defined
[2020-07-21 11:29:52,188] [INFO]: {'provider': 'username', 'Data': {'serial_no': 'bis1'}} [in /home/ubuntu/SIH-2020/app/routes.py:906]
