[2020-07-31 13:20:33,170] [INFO]: {'provider': 'username', 'Data': {'serial_no': 'C7ZzdHdaVeJAZFQH2gnJZo'}} [in /home/ubuntu/SIH-2020/app/routes.py:995]
[2020-07-31 13:20:38,331] [INFO]: {'provider': 'username', 'Data': {'serial_no': 'ETDjbaT4dLdTDkRGqvtLSr'}} [in /home/ubuntu/SIH-2020/app/routes.py:995]
[2020-07-31 13:22:32,641] [INFO]: {'provider': 'username', 'Data': {'serial_no': 'L6C7fzLzt3QkqjxAXHwYqr'}} [in /home/ubuntu/SIH-2020/app/routes.py:995]
[2020-07-31 13:22:32,822] [INFO]: {'provider': 'username', 'Data': {'serial_no': 'L6C7fzLzt3QkqjxAXHwYqr'}} [in /home/ubuntu/SIH-2020/app/routes.py:995]
[2020-07-31 13:25:15,932] [INFO]: {'provider': 'username', 'Data': {'serial_no': '7zWdffH5DsiaUAbrPsKj2X'}} [in /home/ubuntu/SIH-2020/app/routes.py:995]
[2020-07-31 13:28:51,202] [INFO]: {'provider': 'username', 'Data': {'serial_no': 'MXYXBeeeDKuxfRTvZHKXjD'}} [in /home/ubuntu/SIH-2020/app/routes.py:995]
[2020-07-31 13:29:14,553] [INFO]: {'provider': 'username', 'Data': {'serial_no': ' '}} [in /home/ubuntu/SIH-2020/app/routes.py:995]
[2020-07-31 13:29:22,931] [INFO]: <Request 'http://3.215.183.155/api/services/v1/get_po_invoice' [POST]> [in /home/ubuntu/SIH-2020/app/routes.py:505]
[2020-07-31 13:29:22,931] [INFO]: reached po invoice 1 [in /home/ubuntu/SIH-2020/app/routes.py:511]
[2020-07-31 13:29:22,939] [INFO]: po_5f114408e257dd728e757d66.pdf [in /home/ubuntu/SIH-2020/app/routes.py:517]
[2020-07-31 13:29:23,025] [INFO]: http://3.215.183.155/static/po/po_5f114408e257dd728e757d66.pdf [in /home/ubuntu/SIH-2020/app/routes.py:523]
[2020-07-31 13:29:24,204] [INFO]: <Request 'http://3.215.183.155/api/services/v1/get_po_invoice' [POST]> [in /home/ubuntu/SIH-2020/app/routes.py:505]
[2020-07-31 13:29:24,205] [INFO]: reached po invoice 1 [in /home/ubuntu/SIH-2020/app/routes.py:511]
[2020-07-31 13:29:24,210] [ERROR]: Exception on /api/services/v1/get_po_invoice [POST] [in /usr/local/lib/python3.6/dist-packages/flask/app.py:1560]
Traceback (most recent call last):
  File "/home/ubuntu/SIH-2020/app/routes.py", line 514, in get_po_invoice
    content = db.po.find_one({'_id':ObjectId(data['Data']['po_id'])})
KeyError: 'po_id'

During handling of the above exception, another exception occurred:

Traceback (most recent call last):
  File "/usr/local/lib/python3.6/dist-packages/flask/app.py", line 1982, in wsgi_app
    response = self.full_dispatch_request()
  File "/usr/local/lib/python3.6/dist-packages/flask/app.py", line 1614, in full_dispatch_request
    rv = self.handle_user_exception(e)
  File "/usr/local/lib/python3.6/dist-packages/flask/app.py", line 1517, in handle_user_exception
    reraise(exc_type, exc_value, tb)
  File "/usr/local/lib/python3.6/dist-packages/flask/_compat.py", line 33, in reraise
    raise value
  File "/usr/local/lib/python3.6/dist-packages/flask/app.py", line 1612, in full_dispatch_request
    rv = self.dispatch_request()
  File "/usr/local/lib/python3.6/dist-packages/flask/app.py", line 1598, in dispatch_request
    return self.view_functions[rule.endpoint](**req.view_args)
  File "/home/ubuntu/SIH-2020/app/routes.py", line 528, in get_po_invoice
    logger.error(str(e) + "on line no: " + exc_tb.tb_lineno)
NameError: name 'logger' is not defined
[2020-07-31 13:29:53,425] [INFO]: <Request 'http://3.215.183.155/api/services/v1/get_po_invoice' [POST]> [in /home/ubuntu/SIH-2020/app/routes.py:505]
[2020-07-31 13:29:53,426] [INFO]: reached po invoice 1 [in /home/ubuntu/SIH-2020/app/routes.py:511]
[2020-07-31 13:29:53,433] [INFO]: po_5f10af728bdd08981754b329.pdf [in /home/ubuntu/SIH-2020/app/routes.py:517]
[2020-07-31 13:29:53,510] [INFO]: http://3.215.183.155/static/po/po_5f10af728bdd08981754b329.pdf [in /home/ubuntu/SIH-2020/app/routes.py:523]
[2020-07-31 13:29:55,994] [INFO]: <Request 'http://3.215.183.155/api/services/v1/get_po_invoice' [POST]> [in /home/ubuntu/SIH-2020/app/routes.py:505]
[2020-07-31 13:29:55,995] [INFO]: reached po invoice 1 [in /home/ubuntu/SIH-2020/app/routes.py:511]
[2020-07-31 13:29:56,000] [ERROR]: Exception on /api/services/v1/get_po_invoice [POST] [in /usr/local/lib/python3.6/dist-packages/flask/app.py:1560]
Traceback (most recent call last):
  File "/home/ubuntu/SIH-2020/app/routes.py", line 514, in get_po_invoice
    content = db.po.find_one({'_id':ObjectId(data['Data']['po_id'])})
KeyError: 'po_id'

During handling of the above exception, another exception occurred:

Traceback (most recent call last):
  File "/usr/local/lib/python3.6/dist-packages/flask/app.py", line 1982, in wsgi_app
    response = self.full_dispatch_request()
  File "/usr/local/lib/python3.6/dist-packages/flask/app.py", line 1614, in full_dispatch_request
    rv = self.handle_user_exception(e)
  File "/usr/local/lib/python3.6/dist-packages/flask/app.py", line 1517, in handle_user_exception
    reraise(exc_type, exc_value, tb)
  File "/usr/local/lib/python3.6/dist-packages/flask/_compat.py", line 33, in reraise
    raise value
  File "/usr/local/lib/python3.6/dist-packages/flask/app.py", line 1612, in full_dispatch_request
    rv = self.dispatch_request()
  File "/usr/local/lib/python3.6/dist-packages/flask/app.py", line 1598, in dispatch_request
    return self.view_functions[rule.endpoint](**req.view_args)
  File "/home/ubuntu/SIH-2020/app/routes.py", line 528, in get_po_invoice
    logger.error(str(e) + "on line no: " + exc_tb.tb_lineno)
NameError: name 'logger' is not defined
[2020-07-31 13:30:23,306] [INFO]: <Request 'http://3.215.183.155/api/services/v1/get_po_invoice' [POST]> [in /home/ubuntu/SIH-2020/app/routes.py:505]
[2020-07-31 13:30:23,307] [INFO]: reached po invoice 1 [in /home/ubuntu/SIH-2020/app/routes.py:511]
[2020-07-31 13:30:23,314] [INFO]: po_5f10af728bdd08981754b329.pdf [in /home/ubuntu/SIH-2020/app/routes.py:517]
[2020-07-31 13:30:23,388] [INFO]: http://3.215.183.155/static/po/po_5f10af728bdd08981754b329.pdf [in /home/ubuntu/SIH-2020/app/routes.py:523]
[2020-07-31 13:30:34,636] [INFO]: <Request 'http://3.215.183.155/api/services/v1/get_po_invoice' [POST]> [in /home/ubuntu/SIH-2020/app/routes.py:505]
[2020-07-31 13:30:34,637] [INFO]: reached po invoice 1 [in /home/ubuntu/SIH-2020/app/routes.py:511]
[2020-07-31 13:30:34,642] [ERROR]: Exception on /api/services/v1/get_po_invoice [POST] [in /usr/local/lib/python3.6/dist-packages/flask/app.py:1560]
Traceback (most recent call last):
  File "/home/ubuntu/SIH-2020/app/routes.py", line 514, in get_po_invoice
    content = db.po.find_one({'_id':ObjectId(data['Data']['po_id'])})
KeyError: 'po_id'

During handling of the above exception, another exception occurred:

Traceback (most recent call last):
  File "/usr/local/lib/python3.6/dist-packages/flask/app.py", line 1982, in wsgi_app
    response = self.full_dispatch_request()
  File "/usr/local/lib/python3.6/dist-packages/flask/app.py", line 1614, in full_dispatch_request
    rv = self.handle_user_exception(e)
  File "/usr/local/lib/python3.6/dist-packages/flask/app.py", line 1517, in handle_user_exception
    reraise(exc_type, exc_value, tb)
  File "/usr/local/lib/python3.6/dist-packages/flask/_compat.py", line 33, in reraise
    raise value
  File "/usr/local/lib/python3.6/dist-packages/flask/app.py", line 1612, in full_dispatch_request
    rv = self.dispatch_request()
  File "/usr/local/lib/python3.6/dist-packages/flask/app.py", line 1598, in dispatch_request
    return self.view_functions[rule.endpoint](**req.view_args)
  File "/home/ubuntu/SIH-2020/app/routes.py", line 528, in get_po_invoice
    logger.error(str(e) + "on line no: " + exc_tb.tb_lineno)
NameError: name 'logger' is not defined
[2020-07-31 13:35:44,581] [INFO]: <Request 'http://3.215.183.155/api/services/v1/get_so_invoice' [POST]> [in /home/ubuntu/SIH-2020/app/routes.py:540]
[2020-07-31 13:35:44,582] [INFO]: reached so invoice 1 [in /home/ubuntu/SIH-2020/app/routes.py:546]
[2020-07-31 13:35:44,590] [INFO]: so_5f113c6d09ca0c419118e66c.pdf [in /home/ubuntu/SIH-2020/app/routes.py:553]
[2020-07-31 13:35:44,664] [INFO]: http://3.215.183.155/static/so/so_5f113c6d09ca0c419118e66c.pdf [in /home/ubuntu/SIH-2020/app/routes.py:559]
[2020-07-31 13:35:53,320] [INFO]: <Request 'http://3.215.183.155/api/services/v1/get_so_invoice' [POST]> [in /home/ubuntu/SIH-2020/app/routes.py:540]
[2020-07-31 13:35:53,320] [INFO]: reached so invoice 1 [in /home/ubuntu/SIH-2020/app/routes.py:546]
[2020-07-31 13:35:53,330] [INFO]: so_5f157065719e10c7e20f4506.pdf [in /home/ubuntu/SIH-2020/app/routes.py:553]
[2020-07-31 13:35:53,404] [INFO]: http://3.215.183.155/static/so/so_5f157065719e10c7e20f4506.pdf [in /home/ubuntu/SIH-2020/app/routes.py:559]
[2020-07-31 15:26:53,364] [INFO]: <Request 'http://3.215.183.155/api/services/v1/get_po_invoice' [POST]> [in /home/ubuntu/SIH-2020/app/routes.py:505]
[2020-07-31 15:26:53,364] [INFO]: reached po invoice 1 [in /home/ubuntu/SIH-2020/app/routes.py:511]
[2020-07-31 15:26:54,095] [INFO]: po_5f16c15eea95723b48ff59fc.pdf [in /home/ubuntu/SIH-2020/app/routes.py:517]
[2020-07-31 15:26:54,170] [INFO]: http://3.215.183.155/static/po/po_5f16c15eea95723b48ff59fc.pdf [in /home/ubuntu/SIH-2020/app/routes.py:523]
[2020-07-31 15:33:51,568] [INFO]: <Request 'http://3.215.183.155/api/services/v1/get_po_invoice' [POST]> [in /home/ubuntu/SIH-2020/app/routes.py:505]
[2020-07-31 15:33:51,568] [INFO]: reached po invoice 1 [in /home/ubuntu/SIH-2020/app/routes.py:511]
