[2020-07-31 13:20:42,696] [INFO]: {'provider': 'username', 'Data': {'serial_no': '6JWMJZJaPz3Z8ZnEMt63ZH'}} [in /home/ubuntu/SIH-2020/app/routes.py:995]
[2020-07-31 13:25:01,810] [INFO]: {'provider': 'username', 'Data': {'serial_no': 'cUQWnX8AKYHmSPRo8Vegdk'}} [in /home/ubuntu/SIH-2020/app/routes.py:995]
[2020-07-31 13:25:25,910] [INFO]: {'provider': 'username', 'Data': {'serial_no': 'HdYeoJosgKww7u7cG2zWUv'}} [in /home/ubuntu/SIH-2020/app/routes.py:995]
[2020-07-31 13:25:31,464] [INFO]: {'provider': 'username', 'Data': {'serial_no': 'MXYXBeeeDKuxfRTvZHKXjD'}} [in /home/ubuntu/SIH-2020/app/routes.py:995]
[2020-07-31 13:29:45,344] [INFO]: <Request 'http://3.215.183.155/api/services/v1/get_po_invoice' [POST]> [in /home/ubuntu/SIH-2020/app/routes.py:505]
[2020-07-31 13:29:45,344] [INFO]: reached po invoice 1 [in /home/ubuntu/SIH-2020/app/routes.py:511]
[2020-07-31 13:29:45,352] [INFO]: po_5f114408e257dd728e757d66.pdf [in /home/ubuntu/SIH-2020/app/routes.py:517]
[2020-07-31 13:29:45,467] [INFO]: http://3.215.183.155/static/po/po_5f114408e257dd728e757d66.pdf [in /home/ubuntu/SIH-2020/app/routes.py:523]
[2020-07-31 13:30:55,519] [INFO]: <Request 'http://3.215.183.155/api/services/v1/get_po_invoice' [POST]> [in /home/ubuntu/SIH-2020/app/routes.py:505]
[2020-07-31 13:30:55,519] [INFO]: reached po invoice 1 [in /home/ubuntu/SIH-2020/app/routes.py:511]
[2020-07-31 13:30:55,526] [INFO]: po_5f217656dc1245d38023b9e6.pdf [in /home/ubuntu/SIH-2020/app/routes.py:517]
[2020-07-31 13:30:55,600] [INFO]: http://3.215.183.155/static/po/po_5f217656dc1245d38023b9e6.pdf [in /home/ubuntu/SIH-2020/app/routes.py:523]
[2020-07-31 13:30:57,925] [INFO]: <Request 'http://3.215.183.155/api/services/v1/get_po_invoice' [POST]> [in /home/ubuntu/SIH-2020/app/routes.py:505]
[2020-07-31 13:30:57,926] [INFO]: reached po invoice 1 [in /home/ubuntu/SIH-2020/app/routes.py:511]
[2020-07-31 13:30:57,930] [ERROR]: Exception on /api/services/v1/get_po_invoice [POST] [in /usr/local/lib/python3.6/dist-packages/flask/app.py:1560]
Traceback (most recent call last):
  File "/home/ubuntu/SIH-2020/app/routes.py", line 514, in get_po_invoice
    content = db.po.find_one({'_id':ObjectId(data['Data']['po_id'])})
KeyError: 'po_id'

During handling of the above exception, another exception occurred:

Traceback (most recent call last):
  File "/usr/local/lib/python3.6/dist-packages/flask/app.py", line 1982, in wsgi_app
    response = self.full_dispatch_request()
  File "/usr/local/lib/python3.6/dist-packages/flask/app.py", line 1614, in full_dispatch_request
    rv = self.handle_user_exception(e)
  File "/usr/local/lib/python3.6/dist-packages/flask/app.py", line 1517, in handle_user_exception
    reraise(exc_type, exc_value, tb)
  File "/usr/local/lib/python3.6/dist-packages/flask/_compat.py", line 33, in reraise
    raise value
  File "/usr/local/lib/python3.6/dist-packages/flask/app.py", line 1612, in full_dispatch_request
    rv = self.dispatch_request()
  File "/usr/local/lib/python3.6/dist-packages/flask/app.py", line 1598, in dispatch_request
    return self.view_functions[rule.endpoint](**req.view_args)
  File "/home/ubuntu/SIH-2020/app/routes.py", line 528, in get_po_invoice
    logger.error(str(e) + "on line no: " + exc_tb.tb_lineno)
NameError: name 'logger' is not defined
[2020-07-31 13:31:08,145] [INFO]: <Request 'http://3.215.183.155/api/services/v1/get_po_invoice' [POST]> [in /home/ubuntu/SIH-2020/app/routes.py:505]
[2020-07-31 13:31:08,145] [INFO]: reached po invoice 1 [in /home/ubuntu/SIH-2020/app/routes.py:511]
[2020-07-31 13:31:08,150] [ERROR]: Exception on /api/services/v1/get_po_invoice [POST] [in /usr/local/lib/python3.6/dist-packages/flask/app.py:1560]
Traceback (most recent call last):
  File "/home/ubuntu/SIH-2020/app/routes.py", line 514, in get_po_invoice
    content = db.po.find_one({'_id':ObjectId(data['Data']['po_id'])})
KeyError: 'po_id'

During handling of the above exception, another exception occurred:

Traceback (most recent call last):
  File "/usr/local/lib/python3.6/dist-packages/flask/app.py", line 1982, in wsgi_app
    response = self.full_dispatch_request()
  File "/usr/local/lib/python3.6/dist-packages/flask/app.py", line 1614, in full_dispatch_request
    rv = self.handle_user_exception(e)
  File "/usr/local/lib/python3.6/dist-packages/flask/app.py", line 1517, in handle_user_exception
    reraise(exc_type, exc_value, tb)
  File "/usr/local/lib/python3.6/dist-packages/flask/_compat.py", line 33, in reraise
    raise value
  File "/usr/local/lib/python3.6/dist-packages/flask/app.py", line 1612, in full_dispatch_request
    rv = self.dispatch_request()
  File "/usr/local/lib/python3.6/dist-packages/flask/app.py", line 1598, in dispatch_request
    return self.view_functions[rule.endpoint](**req.view_args)
  File "/home/ubuntu/SIH-2020/app/routes.py", line 528, in get_po_invoice
    logger.error(str(e) + "on line no: " + exc_tb.tb_lineno)
NameError: name 'logger' is not defined
[2020-07-31 13:31:12,832] [INFO]: <Request 'http://3.215.183.155/api/services/v1/get_po_invoice' [POST]> [in /home/ubuntu/SIH-2020/app/routes.py:505]
[2020-07-31 13:31:12,832] [INFO]: reached po invoice 1 [in /home/ubuntu/SIH-2020/app/routes.py:511]
[2020-07-31 13:31:12,840] [INFO]: po_5f2172f1aa9c9b385e8b6e7d.pdf [in /home/ubuntu/SIH-2020/app/routes.py:517]
[2020-07-31 13:31:12,913] [INFO]: http://3.215.183.155/static/po/po_5f2172f1aa9c9b385e8b6e7d.pdf [in /home/ubuntu/SIH-2020/app/routes.py:523]
[2020-07-31 13:35:55,645] [INFO]: <Request 'http://3.215.183.155/api/services/v1/get_so_invoice' [POST]> [in /home/ubuntu/SIH-2020/app/routes.py:540]
[2020-07-31 13:35:55,646] [INFO]: reached so invoice 1 [in /home/ubuntu/SIH-2020/app/routes.py:546]
[2020-07-31 13:35:55,650] [ERROR]: Exception on /api/services/v1/get_so_invoice [POST] [in /usr/local/lib/python3.6/dist-packages/flask/app.py:1560]
Traceback (most recent call last):
  File "/home/ubuntu/SIH-2020/app/routes.py", line 549, in get_so_invoice
    cont = db.so.find_one({'_id':ObjectId(data['Data']['so_id'])})
KeyError: 'so_id'

During handling of the above exception, another exception occurred:

Traceback (most recent call last):
  File "/usr/local/lib/python3.6/dist-packages/flask/app.py", line 1982, in wsgi_app
    response = self.full_dispatch_request()
  File "/usr/local/lib/python3.6/dist-packages/flask/app.py", line 1614, in full_dispatch_request
    rv = self.handle_user_exception(e)
  File "/usr/local/lib/python3.6/dist-packages/flask/app.py", line 1517, in handle_user_exception
    reraise(exc_type, exc_value, tb)
  File "/usr/local/lib/python3.6/dist-packages/flask/_compat.py", line 33, in reraise
    raise value
  File "/usr/local/lib/python3.6/dist-packages/flask/app.py", line 1612, in full_dispatch_request
    rv = self.dispatch_request()
  File "/usr/local/lib/python3.6/dist-packages/flask/app.py", line 1598, in dispatch_request
    return self.view_functions[rule.endpoint](**req.view_args)
  File "/home/ubuntu/SIH-2020/app/routes.py", line 564, in get_so_invoice
    logger.error(str(e) + "on line no: " + exc_tb.tb_lineno)
NameError: name 'logger' is not defined
[2020-07-31 13:36:20,648] [INFO]: <Request 'http://3.215.183.155/api/services/v1/get_so_invoice' [POST]> [in /home/ubuntu/SIH-2020/app/routes.py:540]
[2020-07-31 13:36:20,649] [INFO]: reached so invoice 1 [in /home/ubuntu/SIH-2020/app/routes.py:546]
[2020-07-31 13:36:20,658] [INFO]: so_5f15d028719e10c7e20f4507.pdf [in /home/ubuntu/SIH-2020/app/routes.py:553]
[2020-07-31 13:36:20,731] [INFO]: http://3.215.183.155/static/so/so_5f15d028719e10c7e20f4507.pdf [in /home/ubuntu/SIH-2020/app/routes.py:559]
[2020-07-31 13:36:22,610] [INFO]: <Request 'http://3.215.183.155/api/services/v1/get_so_invoice' [POST]> [in /home/ubuntu/SIH-2020/app/routes.py:540]
[2020-07-31 13:36:22,611] [INFO]: reached so invoice 1 [in /home/ubuntu/SIH-2020/app/routes.py:546]
[2020-07-31 13:36:22,616] [ERROR]: Exception on /api/services/v1/get_so_invoice [POST] [in /usr/local/lib/python3.6/dist-packages/flask/app.py:1560]
Traceback (most recent call last):
  File "/home/ubuntu/SIH-2020/app/routes.py", line 549, in get_so_invoice
    cont = db.so.find_one({'_id':ObjectId(data['Data']['so_id'])})
KeyError: 'so_id'

During handling of the above exception, another exception occurred:

Traceback (most recent call last):
  File "/usr/local/lib/python3.6/dist-packages/flask/app.py", line 1982, in wsgi_app
    response = self.full_dispatch_request()
  File "/usr/local/lib/python3.6/dist-packages/flask/app.py", line 1614, in full_dispatch_request
    rv = self.handle_user_exception(e)
  File "/usr/local/lib/python3.6/dist-packages/flask/app.py", line 1517, in handle_user_exception
    reraise(exc_type, exc_value, tb)
  File "/usr/local/lib/python3.6/dist-packages/flask/_compat.py", line 33, in reraise
    raise value
  File "/usr/local/lib/python3.6/dist-packages/flask/app.py", line 1612, in full_dispatch_request
    rv = self.dispatch_request()
  File "/usr/local/lib/python3.6/dist-packages/flask/app.py", line 1598, in dispatch_request
    return self.view_functions[rule.endpoint](**req.view_args)
  File "/home/ubuntu/SIH-2020/app/routes.py", line 564, in get_so_invoice
    logger.error(str(e) + "on line no: " + exc_tb.tb_lineno)
NameError: name 'logger' is not defined
[2020-07-31 15:26:55,805] [INFO]: <Request 'http://3.215.183.155/api/services/v1/get_po_invoice' [POST]> [in /home/ubuntu/SIH-2020/app/routes.py:505]
[2020-07-31 15:26:55,806] [INFO]: reached po invoice 1 [in /home/ubuntu/SIH-2020/app/routes.py:511]
[2020-07-31 15:26:55,839] [INFO]: po_5f16c15eea95723b48ff59fc.pdf [in /home/ubuntu/SIH-2020/app/routes.py:517]
[2020-07-31 15:26:55,914] [INFO]: http://3.215.183.155/static/po/po_5f16c15eea95723b48ff59fc.pdf [in /home/ubuntu/SIH-2020/app/routes.py:523]
[2020-07-31 15:27:58,799] [INFO]: <Request 'http://3.215.183.155/api/services/v1/get_po_invoice' [POST]> [in /home/ubuntu/SIH-2020/app/routes.py:505]
[2020-07-31 15:27:58,799] [INFO]: reached po invoice 1 [in /home/ubuntu/SIH-2020/app/routes.py:511]
[2020-07-31 15:27:58,808] [INFO]: po_5f109c3589d2b31d78a53343.pdf [in /home/ubuntu/SIH-2020/app/routes.py:517]
